Workbook

Sheet Escaneo Diario
A1: GRUPO QUINCE 22 | CONTROL DE INVENTARIOS Y CONTEO CÍCLICO DIARIO
A2: 📅 FECHA ACTUAL | C2: 📦 TOTAL ESCANEOS | E2: 🏷️ PRODUCTOS ÚNICOS | H2: 📊 TOTAL DE PIEZAS | J2: 🚀 ACCIÓN OPERATIVA
A3: =TODAY() | C3: =COUNTIF(C7:C1000, "<>") | E3: =IFERROR(__xludf.DUMMYFUNCTION("IFERROR(ROWS(UNIQUE(FILTER(D7:D1000, D7:D1000<>""""))), 0)"),0.0) | H3: =COUNTIF(C7:C1000, "<>") | J3: FINALIZAR ESCANEO
A4: Jornada en curso | C4: Registros capturados | E4: SKUs distintos | H4: Unidades contadas | J4: Asignar Folios y Archivar
A6: Fecha/Hora | B6: Ubicación/Rack | C6: UPC CODE | D6: SKU | E6: Marca | F6: Descripción | G6: División | H6: Categoría | I6: Talla / Size | J6: Alertas y Duplicados
D7: {=IF($C7="","",IFNA(_xlfn.XLOOKUP($C7,Productos!$A:$A,Productos!$E:$E,IFNA(_xlfn.XLOOKUP(TEXT($C7,"0"),Productos!$A:$A,Productos!$E:$E,IFNA(_xlfn.XLOOKUP(IFERROR(VALUE($C7),""),Productos!$A:$A,Productos!$E:$E,_xlfn.XLOOKUP($C7,Productos!$E:$E,Productos!$E:$E,"NO ENCONTRADO")),"NO ENCONTRADO")),"NO ENCONTRADO")),"NO ENCONTRADO"))} | E7: {=IF(OR($D7="",$D7="NO ENCONTRADO"),"",_xlfn.XLOOKUP($D7,Productos!$E:$E,Productos!$H:$H,""))} | F7: {=IF(OR($D7="",$D7="NO ENCONTRADO"),"",_xlfn.XLOOKUP($D7,Productos!$E:$E,Productos!$I:$I,""))} | G7: {=IF(OR($D7="",$D7="NO ENCONTRADO"),"",_xlfn.XLOOKUP($D7,Productos!$E:$E,Productos!$J:$J,""))} | H7: {=IF(OR($D7="",$D7="NO ENCONTRADO"),"",_xlfn.XLOOKUP($D7,Productos!$E:$E,Productos!$K:$K,""))} | I7: {=IF(OR($D7="",$D7="NO ENCONTRADO"),"",_xlfn.XLOOKUP($D7,Productos!$E:$E,Productos!$F:$F,""))} | J7: =IF($C7="","",IF($D7="NO ENCONTRADO",IF(COUNTIF($C$7:$C$1000,$C7)>1,"⚠️ No encontrado | Duplicado","⚠️ No encontrado"),IF(COUNTIF($C$7:$C$1000,$C7)>1,"⚠️ Duplicado","Verificado")))
D8: {=IF($C8="","",IFNA(_xlfn.XLOOKUP($C8,Productos!$A:$A,Productos!$E:$E,IFNA(_xlfn.XLOOKUP(TEXT($C8,"0"),Productos!$A:$A,Productos!$E:$E,IFNA(_xlfn.XLOOKUP(IFERROR(VALUE($C8),""),Productos!$A:$A,Productos!$E:$E,_xlfn.XLOOKUP($C8,Productos!$E:$E,Productos!$E:$E,"NO ENCONTRADO")),"NO ENCONTRADO")),"NO ENCONTRADO")),"NO ENCONTRADO"))} | E8: {=IF(OR($D8="",$D8="NO ENCONTRADO"),"",_xlfn.XLOOKUP($D8,Productos!$E:$E,Productos!$H:$H,""))} | F8: {=IF(OR($D8="",$D8="NO ENCONTRADO"),"",_xlfn.XLOOKUP($D8,Productos!$E:$E,Productos!$I:$I,""))} | G8: {=IF(OR($D8="",$D8="NO ENCONTRADO"),"",_xlfn.XLOOKUP($D8,Productos!$E:$E,Productos!$J:$J,""))} | H8: {=IF(OR($D8="",$D8="NO ENCONTRADO"),"",_xlfn.XLOOKUP($D8,Productos!$E:$E,Productos!$K:$K,""))} | I8: {=IF(OR($D8="",$D8="NO ENCONTRADO"),"",_xlfn.XLOOKUP($D8,Productos!$E:$E,Productos!$F:$F,""))} | J8: =IF($C8="","",IF($D8="NO ENCONTRADO",IF(COUNTIF($C$7:$C$1000,$C8)>1,"⚠️ No encontrado | Duplicado","⚠️ No encontrado"),IF(COUNTIF($C$7:$C$1000,$C8)>1,"⚠️ Duplicado","Verificado")))
D9: {=IF($C9="","",IFNA(_xlfn.XLOOKUP($C9,Productos!$A:$A,Productos!$E:$E,IFNA(_xlfn.XLOOKUP(TEXT($C9,"0"),Productos!$A:$A,Productos!$E:$E,IFNA(_xlfn.XLOOKUP(IFERROR(VALUE($C9),""),Productos!$A:$A,Productos!$E:$E,_xlfn.XLOOKUP($C9,Productos!$E:$E,Productos!$E:$E,"NO ENCONTRADO")),"NO ENCONTRADO")),"NO ENCONTRADO")),"NO ENCONTRADO"))} | E9: {=IF(OR($D9="",$D9="NO ENCONTRADO"),"",_xlfn.XLOOKUP($D9,Productos!$E:$E,Productos!$H:$H,""))} | F9: {=IF(OR($D9="",$D9="NO ENCONTRADO"),"",_xlfn.XLOOKUP($D9,Productos!$E:$E,Productos!$I:$I,""))} | G9: {=IF(OR($D9="",$D9="NO ENCONTRADO"),"",_xlfn.XLOOKUP($D9,Productos!$E:$E,Productos!$J:$J,""))} | H9: {=IF(OR($D9="",$D9="NO ENCONTRADO"),"",_xlfn.XLOOKUP($D9,Productos!$E:$E,Productos!$K:$K,""))} | I9: {=IF(OR($D9="",$D9="NO ENCONTRADO"),"",_xlfn.XLOOKUP($D9,Productos!$E:$E,Productos!$F:$F,""))} | J9: =IF($C9="","",IF($D9="NO ENCONTRADO",IF(COUNTIF($C$7:$C$1000,$C9)>1,"⚠️ No encontrado | Duplicado","⚠️ No encontrado"),IF(COUNTIF($C$7:$C$1000,$C9)>1,"⚠️ Duplicado","Verificado")))
D10: {=IF($C10="","",IFNA(_xlfn.XLOOKUP($C10,Productos!$A:$A,Productos!$E:$E,IFNA(_xlfn.XLOOKUP(TEXT($C10,"0"),Productos!$A:$A,Productos!$E:$E,IFNA(_xlfn.XLOOKUP(IFERROR(VALUE($C10),""),Productos!$A:$A,Productos!$E:$E,_xlfn.XLOOKUP($C10,Productos!$E:$E,Productos!$E:$E,"NO ENCONTRADO")),"NO ENCONTRADO")),"NO ENCONTRADO")),"NO ENCONTRADO"))} | E10: {=IF(OR($D10="",$D10="NO ENCONTRADO"),"",_xlfn.XLOOKUP($D10,Productos!$E:$E,Productos!$H:$H,""))} | F10: {=IF(OR($D10="",$D10="NO ENCONTRADO"),"",_xlfn.XLOOKUP($D10,Productos!$E:$E,Productos!$I:$I,""))} | G10: {=IF(OR($D10="",$D10="NO ENCONTRADO"),"",_xlfn.XLOOKUP($D10,Productos!$E:$E,Productos!$J:$J,""))} | H10: {=IF(OR($D10="",$D10="NO ENCONTRADO"),"",_xlfn.XLOOKUP($D10,Productos!$E:$E,Productos!$K:$K,""))} | I10: {=IF(OR($D10="",$D10="NO ENCONTRADO"),"",_xlfn.XLOOKUP($D10,Productos!$E:$E,Productos!$F:$F,""))} | J10: =IF($C10="","",IF($D10="NO ENCONTRADO",IF(COUNTIF($C$7:$C$1000,$C10)>1,"⚠️ No encontrado | Duplicado","⚠️ No encontrado"),IF(COUNTIF($C$7:$C$1000,$C10)>1,"⚠️ Duplicado","Verificado")))
D11: {=IF($C11="","",IFNA(_xlfn.XLOOKUP($C11,Productos!$A:$A,Productos!$E:$E,IFNA(_xlfn.XLOOKUP(TEXT($C11,"0"),Productos!$A:$A,Productos!$E:$E,IFNA(_xlfn.XLOOKUP(IFERROR(VALUE($C11),""),Productos!$A:$A,Productos!$E:$E,_xlfn.XLOOKUP($C11,Productos!$E:$E,Productos!$E:$E,"NO ENCONTRADO")),"NO ENCONTRADO")),"NO ENCONTRADO")),"NO ENCONTRADO"))} | E11: {=IF(OR($D11="",$D11="NO ENCONTRADO"),"",_xlfn.XLOOKUP($D11,Productos!$E:$E,Productos!$H:$H,""))} | F11: {=IF(OR($D11="",$D11="NO ENCONTRADO"),"",_xlfn.XLOOKUP($D11,Productos!$E:$E,Productos!$I:$I,""))} | G11: {=IF(OR($D11="",$D11="NO ENCONTRADO"),"",_xlfn.XLOOKUP($D11,Productos!$E:$E,Productos!$J:$J,""))} | H11: {=IF(OR($D11="",$D11="NO ENCONTRADO"),"",_xlfn.XLOOKUP($D11,Productos!$E:$E,Productos!$K:$K,""))} | I11: {=IF(OR($D11="",$D11="NO ENCONTRADO"),"",_xlfn.XLOOKUP($D11,Productos!$E:$E,Productos!$F:$F,""))} | J11: =IF($C11="","",IF($D11="NO ENCONTRADO",IF(COUNTIF($C$7:$C$1000,$C11)>1,"⚠️ No encontrado | Duplicado","⚠️ No encontrado"),IF(COUNTIF($C$7:$C$1000,$C11)>1,"⚠️ Duplicado","Verificado")))
D12: {=IF($C12="","",IFNA(_xlfn.XLOOKUP($C12,Productos!$A:$A,Productos!$E:$E,IFNA(_xlfn.XLOOKUP(TEXT($C12,"0"),Productos!$A:$A,Productos!$E:$E,IFNA(_xlfn.XLOOKUP(IFERROR(VALUE($C12),""),Productos!$A:$A,Productos!$E:$E,_xlfn.XLOOKUP($C12,Productos!$E:$E,Productos!$E:$E,"NO ENCONTRADO")),"NO ENCONTRADO")),"NO ENCONTRADO")),"NO ENCONTRADO"))} | E12: {=IF(OR($D12="",$D12="NO ENCONTRADO"),"",_xlfn.XLOOKUP($D12,Productos!$E:$E,Productos!$H:$H,""))} | F12: {=IF(OR($D12="",$D12="NO ENCONTRADO"),"",_xlfn.XLOOKUP($D12,Productos!$E:$E,Productos!$I:$I,""))} | G12: {=IF(OR($D12="",$D12="NO ENCONTRADO"),"",_xlfn.XLOOKUP($D12,Productos!$E:$E,Productos!$J:$J,""))} | H12: {=IF(OR($D12="",$D12="NO ENCONTRADO"),"",_xlfn.XLOOKUP($D12,Productos!$E:$E,Productos!$K:$K,""))} | I12: {=IF(OR($D12="",$D12="NO ENCONTRADO"),"",_xlfn.XLOOKUP($D12,Productos!$E:$E,Productos!$F:$F,""))} | J12: =IF($C12="","",IF($D12="NO ENCONTRADO",IF(COUNTIF($C$7:$C$1000,$C12)>1,"⚠️ No encontrado | Duplicado","⚠️ No encontrado"),IF(COUNTIF($C$7:$C$1000,$C12)>1,"⚠️ Duplicado","Verificado")))
D13: {=IF($C13="","",IFNA(_xlfn.XLOOKUP($C13,Productos!$A:$A,Productos!$E:$E,IFNA(_xlfn.XLOOKUP(TEXT($C13,"0"),Productos!$A:$A,Productos!$E:$E,IFNA(_xlfn.XLOOKUP(IFERROR(VALUE($C13),""),Productos!$A:$A,Productos!$E:$E,_xlfn.XLOOKUP($C13,Productos!$E:$E,Productos!$E:$E,"NO ENCONTRADO")),"NO ENCONTRADO")),"NO ENCONTRADO")),"NO ENCONTRADO"))} | E13: {=IF(OR($D13="",$D13="NO ENCONTRADO"),"",_xlfn.XLOOKUP($D13,Productos!$E:$E,Productos!$H:$H,""))} | F13: {=IF(OR($D13="",$D13="NO ENCONTRADO"),"",_xlfn.XLOOKUP($D13,Productos!$E:$E,Productos!$I:$I,""))} | G13: {=IF(OR($D13="",$D13="NO ENCONTRADO"),"",_xlfn.XLOOKUP($D13,Productos!$E:$E,Productos!$J:$J,""))} | H13: {=IF(OR($D13="",$D13="NO ENCONTRADO"),"",_xlfn.XLOOKUP($D13,Productos!$E:$E,Productos!$K:$K,""))} | I13: {=IF(OR($D13="",$D13="NO ENCONTRADO"),"",_xlfn.XLOOKUP($D13,Productos!$E:$E,Productos!$F:$F,""))} | J13: =IF($C13="","",IF($D13="NO ENCONTRADO",IF(COUNTIF($C$7:$C$1000,$C13)>1,"⚠️ No encontrado | Duplicado","⚠️ No encontrado"),IF(COUNTIF($C$7:$C$1000,$C13)>1,"⚠️ Duplicado","Verificado")))
D14: {=IF($C14="","",IFNA(_xlfn.XLOOKUP($C14,Productos!$A:$A,Productos!$E:$E,IFNA(_xlfn.XLOOKUP(TEXT($C14,"0"),Productos!$A:$A,Productos!$E:$E,IFNA(_xlfn.XLOOKUP(IFERROR(VALUE($C14),""),Productos!$A:$A,Productos!$E:$E,_xlfn.XLOOKUP($C14,Productos!$E:$E,Productos!$E:$E,"NO ENCONTRADO")),"NO ENCONTRADO")),"NO ENCONTRADO")),"NO ENCONTRADO"))} | E14: {=IF(OR($D14="",$D14="NO ENCONTRADO"),"",_xlfn.XLOOKUP($D14,Productos!$E:$E,Productos!$H:$H,""))} | F14: {=IF(OR($D14="",$D14="NO ENCONTRADO"),"",_xlfn.XLOOKUP($D14,Productos!$E:$E,Productos!$I:$I,""))} | G14: {=IF(OR($D14="",$D14="NO ENCONTRADO"),"",_xlfn.XLOOKUP($D14,Productos!$E:$E,Productos!$J:$J,""))} | H14: {=IF(OR($D14="",$D14="NO ENCONTRADO"),"",_xlfn.XLOOKUP($D14,Productos!$E:$E,Productos!$K:$K,""))} | I14: {=IF(OR($D14="",$D14="NO ENCONTRADO"),"",_xlfn.XLOOKUP($D14,Productos!$E:$E,Productos!$F:$F,""))} | J14: =IF($C14="","",IF($D14="NO ENCONTRADO",IF(COUNTIF($C$7:$C$1000,$C14)>1,"⚠️ No encontrado | Duplicado","⚠️ No encontrado"),IF(COUNTIF($C$7:$C$1000,$C14)>1,"⚠️ Duplicado","Verificado")))
D15: {=IF($C15="","",IFNA(_xlfn.XLOOKUP($C15,Productos!$A:$A,Productos!$E:$E,IFNA(_xlfn.XLOOKUP(TEXT($C15,"0"),Productos!$A:$A,Productos!$E:$E,IFNA(_xlfn.XLOOKUP(IFERROR(VALUE($C15),""),Productos!$A:$A,Productos!$E:$E,_xlfn.XLOOKUP($C15,Productos!$E:$E,Productos!$E:$E,"NO ENCONTRADO")),"NO ENCONTRADO")),"NO ENCONTRADO")),"NO ENCONTRADO"))} | E15: {=IF(OR($D15="",$D15="NO ENCONTRADO"),"",_xlfn.XLOOKUP($D15,Productos!$E:$E,Productos!$H:$H,""))} | F15: {=IF(OR($D15="",$D15="NO ENCONTRADO"),"",_xlfn.XLOOKUP($D15,Productos!$E:$E,Productos!$I:$I,""))} | G15: {=IF(OR($D15="",$D15="NO ENCONTRADO"),"",_xlfn.XLOOKUP($D15,Productos!$E:$E,Productos!$J:$J,""))} | H15: {=IF(OR($D15="",$D15="NO ENCONTRADO"),"",_xlfn.XLOOKUP($D15,Productos!$E:$E,Productos!$K:$K,""))} | I15: {=IF(OR($D15="",$D15="NO ENCONTRADO"),"",_xlfn.XLOOKUP($D15,Productos!$E:$E,Productos!$F:$F,""))} | J15: =IF($C15="","",IF($D15="NO ENCONTRADO",IF(COUNTIF($C$7:$C$1000,$C15)>1,"⚠️ No encontrado | Duplicado","⚠️ No encontrado"),IF(COUNTIF($C$7:$C$1000,$C15)>1,"⚠️ Duplicado","Verificado")))
D16: {=IF($C16="","",IFNA(_xlfn.XLOOKUP($C16,Productos!$A:$A,Productos!$E:$E,IFNA(_xlfn.XLOOKUP(TEXT($C16,"0"),Productos!$A:$A,Productos!$E:$E,IFNA(_xlfn.XLOOKUP(IFERROR(VALUE($C16),""),Productos!$A:$A,Productos!$E:$E,_xlfn.XLOOKUP($C16,Productos!$E:$E,Productos!$E:$E,"NO ENCONTRADO")),"NO ENCONTRADO")),"NO ENCONTRADO")),"NO ENCONTRADO"))} | E16: {=IF(OR($D16="",$D16="NO ENCONTRADO"),"",_xlfn.XLOOKUP($D16,Productos!$E:$E,Productos!$H:$H,""))} | F16: {=IF(OR($D16="",$D16="NO ENCONTRADO"),"",_xlfn.XLOOKUP($D16,Productos!$E:$E,Productos!$I:$I,""))} | G16: {=IF(OR($D16="",$D16="NO ENCONTRADO"),"",_xlfn.XLOOKUP($D16,Productos!$E:$E,Productos!$J:$J,""))} | H16: {=IF(OR($D16="",$D16="NO ENCONTRADO"),"",_xlfn.XLOOKUP($D16,Productos!$E:$E,Productos!$K:$K,""))} | I16: {=IF(OR($D16="",$D16="NO ENCONTRADO"),"",_xlfn.XLOOKUP($D16,Productos!$E:$E,Productos!$F:$F,""))} | J16: =IF($C16="","",IF($D16="NO ENCONTRADO",IF(COUNTIF($C$7:$C$1000,$C16)>1,"⚠️ No encontrado | Duplicado","⚠️ No encontrado"),IF(COUNTIF($C$7:$C$1000,$C16)>1,"⚠️ Duplicado","Verificado")))
D17: {=IF($C17="","",IFNA(_xlfn.XLOOKUP($C17,Productos!$A:$A,Productos!$E:$E,IFNA(_xlfn.XLOOKUP(TEXT($C17,"0"),Productos!$A:$A,Productos!$E:$E,IFNA(_xlfn.XLOOKUP(IFERROR(VALUE($C17),""),Productos!$A:$A,Productos!$E:$E,_xlfn.XLOOKUP($C17,Productos!$E:$E,Productos!$E:$E,"NO ENCONTRADO")),"NO ENCONTRADO")),"NO ENCONTRADO")),"NO ENCONTRADO"))} | E17: {=IF(OR($D17="",$D17="NO ENCONTRADO"),"",_xlfn.XLOOKUP($D17,Productos!$E:$E,Productos!$H:$H,""))} | F17: {=IF(OR($D17="",$D17="NO ENCONTRADO"),"",_xlfn.XLOOKUP($D17,Productos!$E:$E,Productos!$I:$I,""))} | G17: {=IF(OR($D17="",$D17="NO ENCONTRADO"),"",_xlfn.XLOOKUP($D17,Productos!$E:$E,Productos!$J:$J,""))} | H17: {=IF(OR($D17="",$D17="NO ENCONTRADO"),"",_xlfn.XLOOKUP($D17,Productos!$E:$E,Productos!$K:$K,""))} | I17: {=IF(OR($D17="",$D17="NO ENCONTRADO"),"",_xlfn.XLOOKUP($D17,Productos!$E:$E,Productos!$F:$F,""))} | J17: =IF($C17="","",IF($D17="NO ENCONTRADO",IF(COUNTIF($C$7:$C$1000,$C17)>1,"⚠️ No encontrado | Duplicado","⚠️ No encontrado"),IF(COUNTIF($C$7:$C$1000,$C17)>1,"⚠️ Duplicado","Verificado")))
D18: {=IF($C18="","",IFNA(_xlfn.XLOOKUP($C18,Productos!$A:$A,Productos!$E:$E,IFNA(_xlfn.XLOOKUP(TEXT($C18,"0"),Productos!$A:$A,Productos!$E:$E,IFNA(_xlfn.XLOOKUP(IFERROR(VALUE($C18),""),Productos!$A:$A,Productos!$E:$E,_xlfn.XLOOKUP($C18,Productos!$E:$E,Productos!$E:$E,"NO ENCONTRADO")),"NO ENCONTRADO")),"NO ENCONTRADO")),"NO ENCONTRADO"))} | E18: {=IF(OR($D18="",$D18="NO ENCONTRADO"),"",_xlfn.XLOOKUP($D18,Productos!$E:$E,Productos!$H:$H,""))} | F18: {=IF(OR($D18="",$D18="NO ENCONTRADO"),"",_xlfn.XLOOKUP($D18,Productos!$E:$E,Productos!$I:$I,""))} | G18: {=IF(OR($D18="",$D18="NO ENCONTRADO"),"",_xlfn.XLOOKUP($D18,Productos!$E:$E,Productos!$J:$J,""))} | H18: {=IF(OR($D18="",$D18="NO ENCONTRADO"),"",_xlfn.XLOOKUP($D18,Productos!$E:$E,Productos!$K:$K,""))} | I18: {=IF(OR($D18="",$D18="NO ENCONTRADO"),"",_xlfn.XLOOKUP($D18,Productos!$E:$E,Productos!$F:$F,""))} | J18: =IF($C18="","",IF($D18="NO ENCONTRADO",IF(COUNTIF($C$7:$C$1000,$C18)>1,"⚠️ No encontrado | Duplicado","⚠️ No encontrado"),IF(COUNTIF($C$7:$C$1000,$C18)>1,"⚠️ Duplicado","Verificado")))
... D1000: {=IF($C1000="","",IFNA(_xlfn.XLOOKUP($C1000,Productos!$A:$A,Productos!$E:$E,IFNA(_xlfn.XLOOKUP(TEXT($C1000,"0"),Productos!$A:$A,Productos!$E:$E,IFNA(_xlfn.XLOOKUP(IFERROR(VALUE($C1000),""),Productos!$A:$A,Productos!$E:$E,_xlfn.XLOOKUP($C1000,Productos!$E:$E,Productos!$E:$E,"NO ENCONTRADO")),"NO ENCONTRADO")),"NO ENCONTRADO")),"NO ENCONTRADO"))} | E1000: {=IF(OR($D1000="",$D1000="NO ENCONTRADO"),"",_xlfn.XLOOKUP($D1000,Productos!$E:$E,Productos!$H:$H,""))} | F1000: {=IF(OR($D1000="",$D1000="NO ENCONTRADO"),"",_xlfn.XLOOKUP($D1000,Productos!$E:$E,Productos!$I:$I,""))} | G1000: {=IF(OR($D1000="",$D1000="NO ENCONTRADO"),"",_xlfn.XLOOKUP($D1000,Productos!$E:$E,Productos!$J:$J,""))} | H1000: {=IF(OR($D1000="",$D1000="NO ENCONTRADO"),"",_xlfn.XLOOKUP($D1000,Productos!$E:$E,Productos!$K:$K,""))} | I1000: {=IF(OR($D1000="",$D1000="NO ENCONTRADO"),"",_xlfn.XLOOKUP($D1000,Productos!$E:$E,Productos!$F:$F,""))} | J1000: =IF($C1000="","",IF($D1000="NO ENCONTRADO",IF(COUNTIF($C$7:$C$1000,$C1000)>1,"⚠️ No encontrado | Duplicado","⚠️ No encontrado"),IF(COUNTIF($C$7:$C$1000,$C1000)>1,"⚠️ Duplicado","Verificado")))

Sheet Historial de Escaneos
A1: HISTORIAL Y BITÁCORA CONSOLIDADA DE CONTEOS CÍCLICOS - GRUPO QUINCE 22
A2: Registro histórico de auditorías, folios automáticos por ubicación y trazabilidad consolidada de marcas e inventario físico
A3: Fecha de Conteo | B3: Hora Registro | C3: Folio de Escaneo | D3: Ubicación / Rack | E3: Marcas Escaneadas (Todas) | F3: Total Piezas | G3: Auditor / Responsable | H3: Dictamen de Auditoría | I3: Alertas de Modificación / Incidencias

Sheet Escaneos
A1: Folio de Escaneo | B1: Fecha / Hora | C1: Ubicación / Rack | D1: UPC CODE | E1: SKU | F1: Marca | G1: Descripción | H1: Categoría | I1: Talla / Size | J1: Piezas Contadas | K1: Auditor / Responsable | L1: Estado de Conteo | M1: Detalle de Modificaciones / Alertas

Sheet Configuración
A1: CONFIGURACIÓN DEL SISTEMA Y CATÁLOGOS MAESTROS - GRUPO QUINCE 22
A2: Catálogos oficiales para validación de datos y listas desplegables del conteo cíclico diario
A3: Ubicaciones / Racks | B3: Marcas | C3: Categorías | D3: Tallas / Sizes | E3: Auditores / Operadores | F3: Estado de Conteo | H3: Ubicaciones NetSuite (Hoja a Revisar) | I3: SKUs con stock | J3: Piezas en sistema
A4: Pasillo A - Racks Principales | B4: 1522 Original | C4: Playeras | D4: XS | E4: Jesús Fregoso | F4: Verificado | H4: Almacenes G1522 | I4: {=_xlfn.XLOOKUP($H4,Criterios!$G$6:$G$200,Criterios!I$6:I$200,"")} | J4: {=_xlfn.XLOOKUP($H4,Criterios!$G$6:$G$200,Criterios!J$6:J$200,"")}
A5: Pasillo B - Estantería Media | B5: Urban Trend | C5: Pantalones | D5: S | E5: Carlos Morales | F5: Con Discrepancia | H5: AMAZON | I5: {=_xlfn.XLOOKUP($H5,Criterios!$G$6:$G$200,Criterios!I$6:I$200,"")} | J5: {=_xlfn.XLOOKUP($H5,Criterios!$G$6:$G$200,Criterios!J$6:J$200,"")}
A6: Pasillo C - Calzado y Confección | B6: Denim Co. | C6: Sudaderas | D6: M | E6: Andrea Valenzuela | F6: Pendiente | H6: ARIAT CHIHUAHUA | I6: {=_xlfn.XLOOKUP($H6,Criterios!$G$6:$G$200,Criterios!I$6:I$200,"")} | J6: {=_xlfn.XLOOKUP($H6,Criterios!$G$6:$G$200,Criterios!J$6:J$200,"")}
A7: Pasillo D - Accesorios | B7: Active Wear | C7: Chamarras | D7: L | E7: Luis Fernández | F7: Revisión Requerida | H7: ARIAT OUTLET GDL | I7: {=_xlfn.XLOOKUP($H7,Criterios!$G$6:$G$200,Criterios!I$6:I$200,"")} | J7: {=_xlfn.XLOOKUP($H7,Criterios!$G$6:$G$200,Criterios!J$6:J$200,"")}
A8: Pasillo E - Devoluciones | B8: Casual Basics | C8: Gorras | D8: XL | E8: Mariana Garza | H8: ARIAT PLAZA SAN LUIS | I8: {=_xlfn.XLOOKUP($H8,Criterios!$G$6:$G$200,Criterios!I$6:I$200,"")} | J8: {=_xlfn.XLOOKUP($H8,Criterios!$G$6:$G$200,Criterios!J$6:J$200,"")}
A9: Bodega Central - Tarimas | B9: Signature 1522 | C9: Camisas | D9: XXL | E9: Roberto Méndez | H9: ARIAT SAN NICOLAS NL | I9: {=_xlfn.XLOOKUP($H9,Criterios!$G$6:$G$200,Criterios!I$6:I$200,"")} | J9: {=_xlfn.XLOOKUP($H9,Criterios!$G$6:$G$200,Criterios!J$6:J$200,"")}
A10: Zona de Picking 1 | B10: Premium Line | C10: Calzado | D10: 28x32 | E10: Sofía Castro | H10: B25 CEDIS | I10: {=_xlfn.XLOOKUP($H10,Criterios!$G$6:$G$200,Criterios!I$6:I$200,"")} | J10: {=_xlfn.XLOOKUP($H10,Criterios!$G$6:$G$200,Criterios!J$6:J$200,"")}
A11: Zona de Recepción | B11: Vintage Republic | C11: Accesorios | D11: 30x32 | E11: Miguel Ángel Ruiz | H11: B25 STETSON.MX | I11: {=_xlfn.XLOOKUP($H11,Criterios!$G$6:$G$200,Criterios!I$6:I$200,"")} | J11: {=_xlfn.XLOOKUP($H11,Criterios!$G$6:$G$200,Criterios!J$6:J$200,"")}
A12: Almacén General - Cuarentena | B12: Essentials | C12: Ropa Deportiva | D12: 32x32 | E12: Diana Navarro | H12: B25 WB MERCADO LIBRE | I12: {=_xlfn.XLOOKUP($H12,Criterios!$G$6:$G$200,Criterios!I$6:I$200,"")} | J12: {=_xlfn.XLOOKUP($H12,Criterios!$G$6:$G$200,Criterios!J$6:J$200,"")}
A13: Mesa de Empaque | B13: Colección Especial | C13: Ropa Interior | D13: 34x32 | E13: Pedro Gómez | H13: B25 WESTERN BROTHERS.MX | I13: {=_xlfn.XLOOKUP($H13,Criterios!$G$6:$G$200,Criterios!I$6:I$200,"")} | J13: {=_xlfn.XLOOKUP($H13,Criterios!$G$6:$G$200,Criterios!J$6:J$200,"")}
A14: Área de Devoluciones | B14: Edición Limitada | C14: Calcetería | D14: UNITALLA | E14: Laura Sánchez | H14: CAPSLAB Warehouse | I14: {=_xlfn.XLOOKUP($H14,Criterios!$G$6:$G$200,Criterios!I$6:I$200,"")} | J14: {=_xlfn.XLOOKUP($H14,Criterios!$G$6:$G$200,Criterios!J$6:J$200,"")}
A15: J1-L1-01 | B15: Stetson | C15: Jeans | D15: 29 x 32 | H15: CL Muestras | I15: {=_xlfn.XLOOKUP($H15,Criterios!$G$6:$G$200,Criterios!I$6:I$200,"")} | J15: {=_xlfn.XLOOKUP($H15,Criterios!$G$6:$G$200,Criterios!J$6:J$200,"")}
A16: Almacenes G1522 | B16: Ariat | C16: Denim | D16: 30 x 32 | H16: CL POS | I16: {=_xlfn.XLOOKUP($H16,Criterios!$G$6:$G$200,Criterios!I$6:I$200,"")} | J16: {=_xlfn.XLOOKUP($H16,Criterios!$G$6:$G$200,Criterios!J$6:J$200,"")}
A17: AMAZON | B17: CAPSLAB | C17: Ropa | D17: 31 x 32 | H17: CONSIGNA REFLO | I17: {=_xlfn.XLOOKUP($H17,Criterios!$G$6:$G$200,Criterios!I$6:I$200,"")} | J17: {=_xlfn.XLOOKUP($H17,Criterios!$G$6:$G$200,Criterios!J$6:J$200,"")}
A18: ARIAT CHIHUAHUA | B18: Denver | D18: 32 x 34 | H18: CONSIGNAS | I18: {=_xlfn.XLOOKUP($H18,Criterios!$G$6:$G$200,Criterios!I$6:I$200,"")} | J18: {=_xlfn.XLOOKUP($H18,Criterios!$G$6:$G$200,Criterios!J$6:J$200,"")}
A19: ARIAT OUTLET GDL | B19: Generico | D19: 33 x 32 | H19: DEPARTAMENTAL | I19: {=_xlfn.XLOOKUP($H19,Criterios!$G$6:$G$200,Criterios!I$6:I$200,"")} | J19: {=_xlfn.XLOOKUP($H19,Criterios!$G$6:$G$200,Criterios!J$6:J$200,"")}
A20: ARIAT PLAZA SAN LUIS | B20: Happy Socks | D20: 34 x 34 | H20: ECOMMERCE | I20: {=_xlfn.XLOOKUP($H20,Criterios!$G$6:$G$200,Criterios!I$6:I$200,"")} | J20: {=_xlfn.XLOOKUP($H20,Criterios!$G$6:$G$200,Criterios!J$6:J$200,"")}
A21: ARIAT SAN NICOLAS NL | B21: Montana West | D21: 34 x 36 | H21: ENGLISH REP | I21: {=_xlfn.XLOOKUP($H21,Criterios!$G$6:$G$200,Criterios!I$6:I$200,"")} | J21: {=_xlfn.XLOOKUP($H21,Criterios!$G$6:$G$200,Criterios!J$6:J$200,"")}
A22: B25 CEDIS | B22: REFLO | D22: 36 x 32 | H22: EVENTOS (CONSIGNA) | I22: {=_xlfn.XLOOKUP($H22,Criterios!$G$6:$G$200,Criterios!I$6:I$200,"")} | J22: {=_xlfn.XLOOKUP($H22,Criterios!$G$6:$G$200,Criterios!J$6:J$200,"")}
A23: B25 STETSON.MX | B23: Ranch & Corral | D23: 36 x 34 | H23: Fixtures & MKT | I23: {=_xlfn.XLOOKUP($H23,Criterios!$G$6:$G$200,Criterios!I$6:I$200,"")} | J23: {=_xlfn.XLOOKUP($H23,Criterios!$G$6:$G$200,Criterios!J$6:J$200,"")}
A24: B25 WB MERCADO LIBRE | B24: Tru Western | D24: 38 x 32 | H24: FULL MELI | I24: {=_xlfn.XLOOKUP($H24,Criterios!$G$6:$G$200,Criterios!I$6:I$200,"")} | J24: {=_xlfn.XLOOKUP($H24,Criterios!$G$6:$G$200,Criterios!J$6:J$200,"")}
A25: B25 WESTERN BROTHERS.MX | B25: Willow Lane | D25: 32 x 32 | H25: G1522 Defectos | I25: {=_xlfn.XLOOKUP($H25,Criterios!$G$6:$G$200,Criterios!I$6:I$200,"")} | J25: {=_xlfn.XLOOKUP($H25,Criterios!$G$6:$G$200,Criterios!J$6:J$200,"")}
A26: CAPSLAB Warehouse | B26: Wrangler | D26: 34 x 32 | H26: G1522 Lost | I26: {=_xlfn.XLOOKUP($H26,Criterios!$G$6:$G$200,Criterios!I$6:I$200,"")} | J26: {=_xlfn.XLOOKUP($H26,Criterios!$G$6:$G$200,Criterios!J$6:J$200,"")}
A27: CL Muestras | H27: G1522 QA Hold | I27: {=_xlfn.XLOOKUP($H27,Criterios!$G$6:$G$200,Criterios!I$6:I$200,"")} | J27: {=_xlfn.XLOOKUP($H27,Criterios!$G$6:$G$200,Criterios!J$6:J$200,"")}
A28: CL POS | H28: GENERAL | I28: {=_xlfn.XLOOKUP($H28,Criterios!$G$6:$G$200,Criterios!I$6:I$200,"")} | J28: {=_xlfn.XLOOKUP($H28,Criterios!$G$6:$G$200,Criterios!J$6:J$200,"")}
A29: CONSIGNA REFLO | H29: HAPPY SOCKS | I29: {=_xlfn.XLOOKUP($H29,Criterios!$G$6:$G$200,Criterios!I$6:I$200,"")} | J29: {=_xlfn.XLOOKUP($H29,Criterios!$G$6:$G$200,Criterios!J$6:J$200,"")}
A30: CONSIGNAS | H30: HS MERCADO LIBRE | I30: {=_xlfn.XLOOKUP($H30,Criterios!$G$6:$G$200,Criterios!I$6:I$200,"")} | J30: {=_xlfn.XLOOKUP($H30,Criterios!$G$6:$G$200,Criterios!J$6:J$200,"")}
A31: DEPARTAMENTAL | H31: KEY ACCOUNTS | I31: {=_xlfn.XLOOKUP($H31,Criterios!$G$6:$G$200,Criterios!I$6:I$200,"")} | J31: {=_xlfn.XLOOKUP($H31,Criterios!$G$6:$G$200,Criterios!J$6:J$200,"")}
A32: ECOMMERCE | H32: LIVERPOOL MKP | I32: {=_xlfn.XLOOKUP($H32,Criterios!$G$6:$G$200,Criterios!I$6:I$200,"")} | J32: {=_xlfn.XLOOKUP($H32,Criterios!$G$6:$G$200,Criterios!J$6:J$200,"")}
A33: ENGLISH REP | H33: Mercado libre | I33: {=_xlfn.XLOOKUP($H33,Criterios!$G$6:$G$200,Criterios!I$6:I$200,"")} | J33: {=_xlfn.XLOOKUP($H33,Criterios!$G$6:$G$200,Criterios!J$6:J$200,"")}
A34: EVENTOS (CONSIGNA) | H34: MUESTRAS & EXPO | I34: {=_xlfn.XLOOKUP($H34,Criterios!$G$6:$G$200,Criterios!I$6:I$200,"")} | J34: {=_xlfn.XLOOKUP($H34,Criterios!$G$6:$G$200,Criterios!J$6:J$200,"")}
A35: Fixtures & MKT | H35: MUESTRAS REFLO | I35: {=_xlfn.XLOOKUP($H35,Criterios!$G$6:$G$200,Criterios!I$6:I$200,"")} | J35: {=_xlfn.XLOOKUP($H35,Criterios!$G$6:$G$200,Criterios!J$6:J$200,"")}
A36: FULL MELI | H36: Nogales Store | I36: {=_xlfn.XLOOKUP($H36,Criterios!$G$6:$G$200,Criterios!I$6:I$200,"")} | J36: {=_xlfn.XLOOKUP($H36,Criterios!$G$6:$G$200,Criterios!J$6:J$200,"")}
A37: G1522 Defectos | H37: Plaza del Sol Store | I37: {=_xlfn.XLOOKUP($H37,Criterios!$G$6:$G$200,Criterios!I$6:I$200,"")} | J37: {=_xlfn.XLOOKUP($H37,Criterios!$G$6:$G$200,Criterios!J$6:J$200,"")}
A38: G1522 Lost | H38: POTRILLOS | I38: {=_xlfn.XLOOKUP($H38,Criterios!$G$6:$G$200,Criterios!I$6:I$200,"")} | J38: {=_xlfn.XLOOKUP($H38,Criterios!$G$6:$G$200,Criterios!J$6:J$200,"")}
... A52: PUNTO DE VENTA | H52: ZONA SUR | I52: {=_xlfn.XLOOKUP($H52,Criterios!$G$6:$G$200,Criterios!I$6:I$200,"")} | J52: {=_xlfn.XLOOKUP($H52,Criterios!$G$6:$G$200,Criterios!J$6:J$200,"")}
A53: Punto de venta HS
...

Sheet Productos
A1: Código de barras | B1: Identificador interno | C1: Marca principal | D1: WB N.º de estilo | E1: WB SKU | F1: WB Talla | G1: WB Talla de EE. UU. | H1: WB Marca | I1: WB Descripcion | J1: WB División | K1: WB Categoría | L1: WB Género | M1: WB Licencia | N1: WB Temporada | O1: WB Ciclo de vida | P1: WB Color | Q1: WB Fit | R1: WB Silueta | S1: WB Composición | T1: WB Descripción larga | U1: WB País de origen | V1: Unidad | W1: SAT Clave de producto | X1: Enlace de imagen | Y1: Precio de compra | Z1: Precio de venta | AA1: Estatus de Validación | AB1: Detalle de Discrepancias | AC1: 🔍 Panel de Duplicados | AD1: Stock Sistema NetSuite | AE1: Ubicaciones con stock (NetSuite) | AF1: Disponible NetSuite | AG1: Origen del registro | AH1: Notas de enriquecimiento / revisión | AI1: ¿Alguna ubicación en negativo? | AJ1: Ubicaciones con existencia negativa | AK1: Fuentes de consulta | AL1: Precio compra vigente | AM1: Precio venta vigente | AN1: 📍 Ubicación en plataformas (Plataforma + Marca) | AO1: Stock Shopify Stetson México | AP1: Stock Shopify Western Brothers | AQ1: Stock Odoo Universal Unique Brands | AR1: Ubicaciones con stock (plataformas)
A2: 5060923782129 | B2: 79244 | C2: REFLO | D2: ADRIAQU | E2: ADRIAQU-M | F2: M | G2: M | H2: REFLO | I2: Playera tipo polo REFLO Adriatic Aqua/ White | J2: Ropa | K2: Playeras | M2: REFLO | P2: Blanco | S2: Poliéster reciclado | T2: Playera tipo polo de golf REFLO modelo Adriatic en color Aqua/ White, confeccionado con materiales reciclados. Estilo ADRIAQU. | V2: PZS | W2: 53101600 | X2: https://i.ibb.co/k1NTDd3/ADRIAQU.jpg | Y2: 26 | Z2: 1899 | AA2: =IF(AND(A2="", B2="", E2=""), "", IF(AB2="", "Válido", IF((LEN(AB2)-LEN(SUBSTITUTE(AB2,"; ","")))/2+1>(LEN(AB2)-LEN(SUBSTITUTE(AB2,"[Aviso]","")))/7, "Con Incidencias", "Válido"))) | AB2: =IF(AND(A2="", B2="", E2=""), "", TEXTJOIN("; ", TRUE, IF(OR(TRIM(A2&"")="", ISNUMBER(SEARCH("FALTA", A2))), "UPC faltante/inválido", ""), IF(AND(A2<>"", IFERROR(_xlfn.XMATCH(A2,$A$2:$A$653,0,1)<>_xlfn.XMATCH(A2,$A$2:$A$653,0,-1),FALSE)), "Código de barras duplicado", ""), IF(AND(E2<>"", COUNTIF($E$2:$E$653, E2)>1), "SKU duplicado", ""), IF(OR(J2="", J2=""), "[Aviso] División no capturada ()", IF(ISNA(MATCH(J2, Criterios!$A$123:$A$126, 0)), "División no válida", "")), IF(OR(K2="", K2=""), "[Aviso] Categoría no capturada ()", IF(ISNA(MATCH(K2, Criterios!$A$81:$A$120, 0)), "Categoría no válida", IF(AND(J2<>"", J2<>"", J2<>VLOOKUP(K2, Criterios!$A$81:$B$120, 2, FALSE)), "División no coincide con Categoría", ""))), IF(OR(L2="", L2=""), "[Aviso] Género no capturado ()", IF(ISNA(MATCH(L2, Criterios!$B$123:$B$127, 0)), "Género no válido", "")), IF(OR(N2="", N2=""), "[Aviso] Temporada no capturada ()", IF(ISNA(MATCH(N2, Criterios!$C$123:$C$128, 0)), "Temporada no válida", "")), IF(OR(O2="", O2=""), "[Aviso] Ciclo de vida no capturado ()", IF(ISNA(MATCH(O2, Criterios!$D$123:$D$124, 0)), "Ciclo de vida no válido", "")))) | AD2: 7 | AE2: REFLO ALMACEN (4) | AF2: 7 | AG2: Nuevo – NetSuite con existencia | AH2: Género no indicado en NetSuite; Composición: poliéster reciclado (validar % en etiqueta); Físico total NetSuite 7 ≠ suma por ubicación 4 | Revisión 29/09/2026: Marca REFLO fuera de lista Criterios; Campos sin respaldo: L, N, O, Q, U; Auditoría NetSuite 30/09/2026: llenado desde NetSuite [Z] | Homologación G1522 06/10/2026: Validador Shopify: WB: precio con IVA no termina en 9 | AI2: No | AK2: G1522ProductosTodosloscamposSandboxResults894.xlsx: fila 43897 [X,Y]; G1522_Extraccion_Articulos_NetSuite_2026-09-30.xlsx: fila 37577 [Z] | AL2: 26
A3: 5060923782136 | B3: 79245 | C3: REFLO | D3: ADRIAQU | E3: ADRIAQU-L | F3: L | G3: L | H3: REFLO | I3: Playera tipo polo REFLO Adriatic Aqua/ White | J3: Ropa | K3: Playeras | M3: REFLO | P3: Blanco | S3: Poliéster reciclado | T3: Playera tipo polo de golf REFLO modelo Adriatic en color Aqua/ White, confeccionado con materiales reciclados. Estilo ADRIAQU. | V3: PZS | W3: 53101600 | X3: https://i.ibb.co/k1NTDd3/ADRIAQU.jpg | Y3: 26 | Z3: 1899 | AA3: =IF(AND(A3="", B3="", E3=""), "", IF(AB3="", "Válido", IF((LEN(AB3)-LEN(SUBSTITUTE(AB3,"; ","")))/2+1>(LEN(AB3)-LEN(SUBSTITUTE(AB3,"[Aviso]","")))/7, "Con Incidencias", "Válido"))) | AB3: =IF(AND(A3="", B3="", E3=""), "", TEXTJOIN("; ", TRUE, IF(OR(TRIM(A3&"")="", ISNUMBER(SEARCH("FALTA", A3))), "UPC faltante/inválido", ""), IF(AND(A3<>"", IFERROR(_xlfn.XMATCH(A3,$A$2:$A$653,0,1)<>_xlfn.XMATCH(A3,$A$2:$A$653,0,-1),FALSE)), "Código de barras duplicado", ""), IF(AND(E3<>"", COUNTIF($E$2:$E$653, E3)>1), "SKU duplicado", ""), IF(OR(J3="", J3=""), "[Aviso] División no capturada ()", IF(ISNA(MATCH(J3, Criterios!$A$123:$A$126, 0)), "División no válida", "")), IF(OR(K3="", K3=""), "[Aviso] Categoría no capturada ()", IF(ISNA(MATCH(K3, Criterios!$A$81:$A$120, 0)), "Categoría no válida", IF(AND(J3<>"", J3<>"", J3<>VLOOKUP(K3, Criterios!$A$81:$B$120, 2, FALSE)), "División no coincide con Categoría", ""))), IF(OR(L3="", L3=""), "[Aviso] Género no capturado ()", IF(ISNA(MATCH(L3, Criterios!$B$123:$B$127, 0)), "Género no válido", "")), IF(OR(N3="", N3=""), "[Aviso] Temporada no capturada ()", IF(ISNA(MATCH(N3, Criterios!$C$123:$C$128, 0)), "Temporada no válida", "")), IF(OR(O3="", O3=""), "[Aviso] Ciclo de vida no capturado ()", IF(ISNA(MATCH(O3, Criterios!$D$123:$D$124, 0)), "Ciclo de vida no válido", "")))) | AD3: 10 | AE3: MUESTRAS REFLO (1); REFLO ALMACEN (5) | AF3: 9 | AG3: Nuevo – NetSuite con existencia | AH3: Género no indicado en NetSuite; Composición: poliéster reciclado (validar % en etiqueta); Físico total NetSuite 10 ≠ suma por ubicación 6 | Revisión 29/09/2026: Marca REFLO fuera de lista Criterios; Campos sin respaldo: L, N, O, Q, U; Auditoría NetSuite 30/09/2026: llenado desde NetSuite [Z] | Homologación G1522 06/10/2026: Validador Shopify: WB: precio con IVA no termina en 9 | AI3: No | AK3: G1522ProductosTodosloscamposSandboxResults894.xlsx: fila 43898 [X,Y]; G1522_Extraccion_Articulos_NetSuite_2026-09-30.xlsx: fila 37578 [Z] | AL3: 26
A4: 5060923782150 | B4: 79246 | C4: REFLO | D4: ADRIAQU | E4: ADRIAQU-XXL | F4: XXL | G4: XXL | H4: REFLO | I4: Playera tipo polo REFLO Adriatic Aqua/ White | J4: Ropa | K4: Playeras | M4: REFLO | P4: Blanco | S4: Poliéster reciclado | T4: Playera tipo polo de golf REFLO modelo Adriatic en color Aqua/ White, confeccionado con materiales reciclados. Estilo ADRIAQU. | V4: PZS | W4: 53101600 | X4: https://i.ibb.co/k1NTDd3/ADRIAQU.jpg | Y4: 26 | Z4: 1899 | AA4: =IF(AND(A4="", B4="", E4=""), "", IF(AB4="", "Válido", IF((LEN(AB4)-LEN(SUBSTITUTE(AB4,"; ","")))/2+1>(LEN(AB4)-LEN(SUBSTITUTE(AB4,"[Aviso]","")))/7, "Con Incidencias", "Válido"))) | AB4: =IF(AND(A4="", B4="", E4=""), "", TEXTJOIN("; ", TRUE, IF(OR(TRIM(A4&"")="", ISNUMBER(SEARCH("FALTA", A4))), "UPC faltante/inválido", ""), IF(AND(A4<>"", IFERROR(_xlfn.XMATCH(A4,$A$2:$A$653,0,1)<>_xlfn.XMATCH(A4,$A$2:$A$653,0,-1),FALSE)), "Código de barras duplicado", ""), IF(AND(E4<>"", COUNTIF($E$2:$E$653, E4)>1), "SKU duplicado", ""), IF(OR(J4="", J4=""), "[Aviso] División no capturada ()", IF(ISNA(MATCH(J4, Criterios!$A$123:$A$126, 0)), "División no válida", "")), IF(OR(K4="", K4=""), "[Aviso] Categoría no capturada ()", IF(ISNA(MATCH(K4, Criterios!$A$81:$A$120, 0)), "Categoría no válida", IF(AND(J4<>"", J4<>"", J4<>VLOOKUP(K4, Criterios!$A$81:$B$120, 2, FALSE)), "División no coincide con Categoría", ""))), IF(OR(L4="", L4=""), "[Aviso] Género no capturado ()", IF(ISNA(MATCH(L4, Criterios!$B$123:$B$127, 0)), "Género no válido", "")), IF(OR(N4="", N4=""), "[Aviso] Temporada no capturada ()", IF(ISNA(MATCH(N4, Criterios!$C$123:$C$128, 0)), "Temporada no válida", "")), IF(OR(O4="", O4=""), "[Aviso] Ciclo de vida no capturado ()", IF(ISNA(MATCH(O4, Criterios!$D$123:$D$124, 0)), "Ciclo de vida no válido", "")))) | AD4: 2 | AE4: REFLO ALMACEN (1) | AF4: 2 | AG4: Nuevo – NetSuite con existencia | AH4: Género no indicado en NetSuite; Composición: poliéster reciclado (validar % en etiqueta); Físico total NetSuite 2 ≠ suma por ubicación 1 | Revisión 29/09/2026: Marca REFLO fuera de lista Criterios; Campos sin respaldo: L, N, O, Q, U; Auditoría NetSuite 30/09/2026: llenado desde NetSuite [Z] | Homologación G1522 06/10/2026: Validador Shopify: WB: precio con IVA no termina en 9 | AI4: No | AK4: G1522ProductosTodosloscamposSandboxResults894.xlsx: fila 43899 [X,Y]; G1522_Extraccion_Articulos_NetSuite_2026-09-30.xlsx: fila 37579 [Z] | AL4: 26
A5: 5060923782112 | B5: 84419 | C5: REFLO | D5: ADRIAQU | E5: ADRIAQU-S | F5: S | G5: S | H5: REFLO | I5: Playera tipo polo REFLO Adriatic Aqua/White | J5: Ropa | K5: Playeras | M5: REFLO | P5: Blanco | S5: Poliéster reciclado | T5: Playera tipo polo de golf REFLO modelo Adriatic en color Aqua/White, confeccionado con materiales reciclados. Estilo ADRIAQU. | V5: PZS | W5: 53101600 | X5: https://i.ibb.co/k1NTDd3/ADRIAQU.jpg | Y5: 26 | Z5: 1899 | AA5: =IF(AND(A5="", B5="", E5=""), "", IF(AB5="", "Válido", IF((LEN(AB5)-LEN(SUBSTITUTE(AB5,"; ","")))/2+1>(LEN(AB5)-LEN(SUBSTITUTE(AB5,"[Aviso]","")))/7, "Con Incidencias", "Válido"))) | AB5: =IF(AND(A5="", B5="", E5=""), "", TEXTJOIN("; ", TRUE, IF(OR(TRIM(A5&"")="", ISNUMBER(SEARCH("FALTA", A5))), "UPC faltante/inválido", ""), IF(AND(A5<>"", IFERROR(_xlfn.XMATCH(A5,$A$2:$A$653,0,1)<>_xlfn.XMATCH(A5,$A$2:$A$653,0,-1),FALSE)), "Código de barras duplicado", ""), IF(AND(E5<>"", COUNTIF($E$2:$E$653, E5)>1), "SKU duplicado", ""), IF(OR(J5="", J5=""), "[Aviso] División no capturada ()", IF(ISNA(MATCH(J5, Criterios!$A$123:$A$126, 0)), "División no válida", "")), IF(OR(K5="", K5=""), "[Aviso] Categoría no capturada ()", IF(ISNA(MATCH(K5, Criterios!$A$81:$A$120, 0)), "Categoría no válida", IF(AND(J5<>"", J5<>"", J5<>VLOOKUP(K5, Criterios!$A$81:$B$120, 2, FALSE)), "División no coincide con Categoría", ""))), IF(OR(L5="", L5=""), "[Aviso] Género no capturado ()", IF(ISNA(MATCH(L5, Criterios!$B$123:$B$127, 0)), "Género no válido", "")), IF(OR(N5="", N5=""), "[Aviso] Temporada no capturada ()", IF(ISNA(MATCH(N5, Criterios!$C$123:$C$128, 0)), "Temporada no válida", "")), IF(OR(O5="", O5=""), "[Aviso] Ciclo de vida no capturado ()", IF(ISNA(MATCH(O5, Criterios!$D$123:$D$124, 0)), "Ciclo de vida no válido", "")))) | AD5: 8 | AE5: REFLO ALMACEN (2); CONSIGNA REFLO (2) | AF5: 8 | AG5: Nuevo – NetSuite con existencia | AH5: Género no indicado en NetSuite; Composición: poliéster reciclado (validar % en etiqueta); Físico total NetSuite 8 ≠ suma por ubicación 4 | Revisión 29/09/2026: Marca REFLO fuera de lista Criterios; Campos sin respaldo: L, N, O, Q, U; Auditoría NetSuite 30/09/2026: llenado desde NetSuite [Z] | Homologación G1522 06/10/2026: Validador Shopify: WB: precio con IVA no termina en 9 | AI5: No | AK5: G1522ProductosTodosloscamposSandboxResults894.xlsx: fila 43901 [X,Y]; G1522_Extraccion_Articulos_NetSuite_2026-09-30.xlsx: fila 39588 [Z] | AL5: 26
A6: 5060923782068 | B6: 79247 | C6: REFLO | D6: ADRICLO | E6: ADRICLO-M | F6: M | G6: M | H6: REFLO | I6: Playera tipo polo REFLO Adriatic Cloud/ Black | J6: Ropa | K6: Playeras | M6: REFLO | P6: Negro | S6: Poliéster reciclado | T6: Playera tipo polo de golf REFLO modelo Adriatic en color Cloud/ Black, confeccionado con materiales reciclados. Estilo ADRICLO. | V6: PZS | W6: 53101600 | X6: https://i.ibb.co/VSDV4Mp/ADRICLO.jpg | Y6: 26 | Z6: 1899 | AA6: =IF(AND(A6="", B6="", E6=""), "", IF(AB6="", "Válido", IF((LEN(AB6)-LEN(SUBSTITUTE(AB6,"; ","")))/2+1>(LEN(AB6)-LEN(SUBSTITUTE(AB6,"[Aviso]","")))/7, "Con Incidencias", "Válido"))) | AB6: =IF(AND(A6="", B6="", E6=""), "", TEXTJOIN("; ", TRUE, IF(OR(TRIM(A6&"")="", ISNUMBER(SEARCH("FALTA", A6))), "UPC faltante/inválido", ""), IF(AND(A6<>"", IFERROR(_xlfn.XMATCH(A6,$A$2:$A$653,0,1)<>_xlfn.XMATCH(A6,$A$2:$A$653,0,-1),FALSE)), "Código de barras duplicado", ""), IF(AND(E6<>"", COUNTIF($E$2:$E$653, E6)>1), "SKU duplicado", ""), IF(OR(J6="", J6=""), "[Aviso] División no capturada ()", IF(ISNA(MATCH(J6, Criterios!$A$123:$A$126, 0)), "División no válida", "")), IF(OR(K6="", K6=""), "[Aviso] Categoría no capturada ()", IF(ISNA(MATCH(K6, Criterios!$A$81:$A$120, 0)), "Categoría no válida", IF(AND(J6<>"", J6<>"", J6<>VLOOKUP(K6, Criterios!$A$81:$B$120, 2, FALSE)), "División no coincide con Categoría", ""))), IF(OR(L6="", L6=""), "[Aviso] Género no capturado ()", IF(ISNA(MATCH(L6, Criterios!$B$123:$B$127, 0)), "Género no válido", "")), IF(OR(N6="", N6=""), "[Aviso] Temporada no capturada ()", IF(ISNA(MATCH(N6, Criterios!$C$123:$C$128, 0)), "Temporada no válida", "")), IF(OR(O6="", O6=""), "[Aviso] Ciclo de vida no capturado ()", IF(ISNA(MATCH(O6, Criterios!$D$123:$D$124, 0)), "Ciclo de vida no válido", "")))) | AD6: 8 | AE6: REFLO ALMACEN (6) | AF6: 10 | AG6: Nuevo – NetSuite con existencia | AH6: Género no indicado en NetSuite; Composición: poliéster reciclado (validar % en etiqueta); Físico total NetSuite 8 ≠ suma por ubicación 4 | Revisión 29/09/2026: Marca REFLO fuera de lista Criterios; Campos sin respaldo: L, N, O, Q, U; Auditoría NetSuite 30/09/2026: llenado desde NetSuite [Z] | Homologación G1522 06/10/2026: Validador Shopify: WB: precio con IVA no termina en 9 | AI6: Sí | AJ6: CONSIGNA REFLO (-2) | AK6: G1522ProductosTodosloscamposSandboxResults894.xlsx: fila 43903 [X,Y]; G1522_Extraccion_Articulos_NetSuite_2026-09-30.xlsx: fila 37580 [Z] | AL6: 26
A7: 5060923782075 | B7: 79248 | C7: REFLO | D7: ADRICLO | E7: ADRICLO-L | F7: L | G7: L | H7: REFLO | I7: Playera tipo polo REFLO Adriatic Cloud/ Black | J7: Ropa | K7: Playeras | M7: REFLO | P7: Negro | S7: Poliéster reciclado | T7: Playera tipo polo de golf REFLO modelo Adriatic en color Cloud/ Black, confeccionado con materiales reciclados. Estilo ADRICLO. | V7: PZS | W7: 53101600 | X7: https://i.ibb.co/VSDV4Mp/ADRICLO.jpg | Y7: 26 | Z7: 1899 | AA7: =IF(AND(A7="", B7="", E7=""), "", IF(AB7="", "Válido", IF((LEN(AB7)-LEN(SUBSTITUTE(AB7,"; ","")))/2+1>(LEN(AB7)-LEN(SUBSTITUTE(AB7,"[Aviso]","")))/7, "Con Incidencias", "Válido"))) | AB7: =IF(AND(A7="", B7="", E7=""), "", TEXTJOIN("; ", TRUE, IF(OR(TRIM(A7&"")="", ISNUMBER(SEARCH("FALTA", A7))), "UPC faltante/inválido", ""), IF(AND(A7<>"", IFERROR(_xlfn.XMATCH(A7,$A$2:$A$653,0,1)<>_xlfn.XMATCH(A7,$A$2:$A$653,0,-1),FALSE)), "Código de barras duplicado", ""), IF(AND(E7<>"", COUNTIF($E$2:$E$653, E7)>1), "SKU duplicado", ""), IF(OR(J7="", J7=""), "[Aviso] División no capturada ()", IF(ISNA(MATCH(J7, Criterios!$A$123:$A$126, 0)), "División no válida", "")), IF(OR(K7="", K7=""), "[Aviso] Categoría no capturada ()", IF(ISNA(MATCH(K7, Criterios!$A$81:$A$120, 0)), "Categoría no válida", IF(AND(J7<>"", J7<>"", J7<>VLOOKUP(K7, Criterios!$A$81:$B$120, 2, FALSE)), "División no coincide con Categoría", ""))), IF(OR(L7="", L7=""), "[Aviso] Género no capturado ()", IF(ISNA(MATCH(L7, Criterios!$B$123:$B$127, 0)), "Género no válido", "")), IF(OR(N7="", N7=""), "[Aviso] Temporada no capturada ()", IF(ISNA(MATCH(N7, Criterios!$C$123:$C$128, 0)), "Temporada no válida", "")), IF(OR(O7="", O7=""), "[Aviso] Ciclo de vida no capturado ()", IF(ISNA(MATCH(O7, Criterios!$D$123:$D$124, 0)), "Ciclo de vida no válido", "")))) | AD7: 10 | AE7: MUESTRAS REFLO (1); REFLO ALMACEN (7) | AF7: 11 | AG7: Nuevo – NetSuite con existencia | AH7: Género no indicado en NetSuite; Composición: poliéster reciclado (validar % en etiqueta); Físico total NetSuite 10 ≠ suma por ubicación 6 | Revisión 29/09/2026: Marca REFLO fuera de lista Criterios; Campos sin respaldo: L, N, O, Q, U; Auditoría NetSuite 30/09/2026: llenado desde NetSuite [Z] | Homologación G1522 06/10/2026: Validador Shopify: WB: precio con IVA no termina en 9 | AI7: Sí | AJ7: CONSIGNA REFLO (-2) | AK7: G1522ProductosTodosloscamposSandboxResults894.xlsx: fila 43904 [X,Y]; G1522_Extraccion_Articulos_NetSuite_2026-09-30.xlsx: fila 37581 [Z] | AL7: 26
A8: 5060923782082 | B8: 79249 | C8: REFLO | D8: ADRICLO | E8: ADRICLO-XL | F8: XL | G8: XL | H8: REFLO | I8: Playera tipo polo REFLO Adriatic Cloud/ Black | J8: Ropa | K8: Playeras | M8: REFLO | P8: Negro | S8: Poliéster reciclado | T8: Playera tipo polo de golf REFLO modelo Adriatic en color Cloud/ Black, confeccionado con materiales reciclados. Estilo ADRICLO. | V8: PZS | W8: 53101600 | X8: https://i.ibb.co/VSDV4Mp/ADRICLO.jpg | Y8: 26 | Z8: 1899 | AA8: =IF(AND(A8="", B8="", E8=""), "", IF(AB8="", "Válido", IF((LEN(AB8)-LEN(SUBSTITUTE(AB8,"; ","")))/2+1>(LEN(AB8)-LEN(SUBSTITUTE(AB8,"[Aviso]","")))/7, "Con Incidencias", "Válido"))) | AB8: =IF(AND(A8="", B8="", E8=""), "", TEXTJOIN("; ", TRUE, IF(OR(TRIM(A8&"")="", ISNUMBER(SEARCH("FALTA", A8))), "UPC faltante/inválido", ""), IF(AND(A8<>"", IFERROR(_xlfn.XMATCH(A8,$A$2:$A$653,0,1)<>_xlfn.XMATCH(A8,$A$2:$A$653,0,-1),FALSE)), "Código de barras duplicado", ""), IF(AND(E8<>"", COUNTIF($E$2:$E$653, E8)>1), "SKU duplicado", ""), IF(OR(J8="", J8=""), "[Aviso] División no capturada ()", IF(ISNA(MATCH(J8, Criterios!$A$123:$A$126, 0)), "División no válida", "")), IF(OR(K8="", K8=""), "[Aviso] Categoría no capturada ()", IF(ISNA(MATCH(K8, Criterios!$A$81:$A$120, 0)), "Categoría no válida", IF(AND(J8<>"", J8<>"", J8<>VLOOKUP(K8, Criterios!$A$81:$B$120, 2, FALSE)), "División no coincide con Categoría", ""))), IF(OR(L8="", L8=""), "[Aviso] Género no capturado ()", IF(ISNA(MATCH(L8, Criterios!$B$123:$B$127, 0)), "Género no válido", "")), IF(OR(N8="", N8=""), "[Aviso] Temporada no capturada ()", IF(ISNA(MATCH(N8, Criterios!$C$123:$C$128, 0)), "Temporada no válida", "")), IF(OR(O8="", O8=""), "[Aviso] Ciclo de vida no capturado ()", IF(ISNA(MATCH(O8, Criterios!$D$123:$D$124, 0)), "Ciclo de vida no válido", "")))) | AD8: 13 | AE8: REFLO ALMACEN (8) | AF8: 14 | AG8: Nuevo – NetSuite con existencia | AH8: Género no indicado en NetSuite; Composición: poliéster reciclado (validar % en etiqueta); Físico total NetSuite 13 ≠ suma por ubicación 7 | Revisión 29/09/2026: Marca REFLO fuera de lista Criterios; Campos sin respaldo: L, N, O, Q, U; Auditoría NetSuite 30/09/2026: llenado desde NetSuite [Z] | Homologación G1522 06/10/2026: Validador Shopify: WB: precio con IVA no termina en 9 | AI8: Sí | AJ8: CONSIGNA REFLO (-1) | AK8: G1522ProductosTodosloscamposSandboxResults894.xlsx: fila 43905 [X,Y]; G1522_Extraccion_Articulos_NetSuite_2026-09-30.xlsx: fila 37582 [Z] | AL8: 26
A9: 5060923782099 | B9: 79250 | C9: REFLO | D9: ADRICLO | E9: ADRICLO-XXL | F9: XXL | G9: XXL | H9: REFLO | I9: Playera tipo polo REFLO Adriatic Cloud/ Black | J9: Ropa | K9: Playeras | M9: REFLO | P9: Negro | S9: Poliéster reciclado | T9: Playera tipo polo de golf REFLO modelo Adriatic en color Cloud/ Black, confeccionado con materiales reciclados. Estilo ADRICLO. | V9: PZS | W9: 53101600 | X9: https://i.ibb.co/VSDV4Mp/ADRICLO.jpg | Y9: 26 | Z9: 1899 | AA9: =IF(AND(A9="", B9="", E9=""), "", IF(AB9="", "Válido", IF((LEN(AB9)-LEN(SUBSTITUTE(AB9,"; ","")))/2+1>(LEN(AB9)-LEN(SUBSTITUTE(AB9,"[Aviso]","")))/7, "Con Incidencias", "Válido"))) | AB9: =IF(AND(A9="", B9="", E9=""), "", TEXTJOIN("; ", TRUE, IF(OR(TRIM(A9&"")="", ISNUMBER(SEARCH("FALTA", A9))), "UPC faltante/inválido", ""), IF(AND(A9<>"", IFERROR(_xlfn.XMATCH(A9,$A$2:$A$653,0,1)<>_xlfn.XMATCH(A9,$A$2:$A$653,0,-1),FALSE)), "Código de barras duplicado", ""), IF(AND(E9<>"", COUNTIF($E$2:$E$653, E9)>1), "SKU duplicado", ""), IF(OR(J9="", J9=""), "[Aviso] División no capturada ()", IF(ISNA(MATCH(J9, Criterios!$A$123:$A$126, 0)), "División no válida", "")), IF(OR(K9="", K9=""), "[Aviso] Categoría no capturada ()", IF(ISNA(MATCH(K9, Criterios!$A$81:$A$120, 0)), "Categoría no válida", IF(AND(J9<>"", J9<>"", J9<>VLOOKUP(K9, Criterios!$A$81:$B$120, 2, FALSE)), "División no coincide con Categoría", ""))), IF(OR(L9="", L9=""), "[Aviso] Género no capturado ()", IF(ISNA(MATCH(L9, Criterios!$B$123:$B$127, 0)), "Género no válido", "")), IF(OR(N9="", N9=""), "[Aviso] Temporada no capturada ()", IF(ISNA(MATCH(N9, Criterios!$C$123:$C$128, 0)), "Temporada no válida", "")), IF(OR(O9="", O9=""), "[Aviso] Ciclo de vida no capturado ()", IF(ISNA(MATCH(O9, Criterios!$D$123:$D$124, 0)), "Ciclo de vida no válido", "")))) | AD9: 8 | AE9: REFLO ALMACEN (5) | AF9: 9 | AG9: Nuevo – NetSuite con existencia | AH9: Género no indicado en NetSuite; Composición: poliéster reciclado (validar % en etiqueta); Físico total NetSuite 8 ≠ suma por ubicación 4 | Revisión 29/09/2026: Marca REFLO fuera de lista Criterios; Campos sin respaldo: L, N, O, Q, U; Auditoría NetSuite 30/09/2026: llenado desde NetSuite [Z] | Homologación G1522 06/10/2026: Validador Shopify: WB: precio con IVA no termina en 9 | AI9: Sí | AJ9: CONSIGNA REFLO (-1) | AK9: G1522ProductosTodosloscamposSandboxResults894.xlsx: fila 43906 [X,Y]; G1522_Extraccion_Articulos_NetSuite_2026-09-30.xlsx: fila 37583 [Z] | AL9: 26
A10: 5060923782051 | B10: 84420 | C10: REFLO | D10: ADRICLO | E10: ADRICLO-S | F10: S | G10: S | H10: REFLO | I10: Playera tipo polo REFLO Adriatic Cloud/Black | J10: Ropa | K10: Playeras | M10: REFLO | P10: Negro | S10: Poliéster reciclado | T10: Playera tipo polo de golf REFLO modelo Adriatic en color Cloud/Black, confeccionado con materiales reciclados. Estilo ADRICLO. | V10: PZS | W10: 53101600 | X10: https://i.ibb.co/VSDV4Mp/ADRICLO.jpg | Y10: 26 | Z10: 1899 | AA10: =IF(AND(A10="", B10="", E10=""), "", IF(AB10="", "Válido", IF((LEN(AB10)-LEN(SUBSTITUTE(AB10,"; ","")))/2+1>(LEN(AB10)-LEN(SUBSTITUTE(AB10,"[Aviso]","")))/7, "Con Incidencias", "Válido"))) | AB10: =IF(AND(A10="", B10="", E10=""), "", TEXTJOIN("; ", TRUE, IF(OR(TRIM(A10&"")="", ISNUMBER(SEARCH("FALTA", A10))), "UPC faltante/inválido", ""), IF(AND(A10<>"", IFERROR(_xlfn.XMATCH(A10,$A$2:$A$653,0,1)<>_xlfn.XMATCH(A10,$A$2:$A$653,0,-1),FALSE)), "Código de barras duplicado", ""), IF(AND(E10<>"", COUNTIF($E$2:$E$653, E10)>1), "SKU duplicado", ""), IF(OR(J10="", J10=""), "[Aviso] División no capturada ()", IF(ISNA(MATCH(J10, Criterios!$A$123:$A$126, 0)), "División no válida", "")), IF(OR(K10="", K10=""), "[Aviso] Categoría no capturada ()", IF(ISNA(MATCH(K10, Criterios!$A$81:$A$120, 0)), "Categoría no válida", IF(AND(J10<>"", J10<>"", J10<>VLOOKUP(K10, Criterios!$A$81:$B$120, 2, FALSE)), "División no coincide con Categoría", ""))), IF(OR(L10="", L10=""), "[Aviso] Género no capturado ()", IF(ISNA(MATCH(L10, Criterios!$B$123:$B$127, 0)), "Género no válido", "")), IF(OR(N10="", N10=""), "[Aviso] Temporada no capturada ()", IF(ISNA(MATCH(N10, Criterios!$C$123:$C$128, 0)), "Temporada no válida", "")), IF(OR(O10="", O10=""), "[Aviso] Ciclo de vida no capturado ()", IF(ISNA(MATCH(O10, Criterios!$D$123:$D$124, 0)), "Ciclo de vida no válido", "")))) | AD10: 8 | AE10: REFLO ALMACEN (4) | AF10: 8 | AG10: Nuevo – NetSuite con existencia | AH10: Género no indicado en NetSuite; Composición: poliéster reciclado (validar % en etiqueta); Físico total NetSuite 8 ≠ suma por ubicación 4 | Revisión 29/09/2026: Marca REFLO fuera de lista Criterios; Campos sin respaldo: L, N, O, Q, U; Auditoría NetSuite 30/09/2026: llenado desde NetSuite [Z] | Homologación G1522 06/10/2026: Validador Shopify: WB: precio con IVA no termina en 9 | AI10: No | AK10: G1522ProductosTodosloscamposSandboxResults894.xlsx: fila 43908 [X,Y]; G1522_Extraccion_Articulos_NetSuite_2026-09-30.xlsx: fila 39589 [Z] | AL10: 26
A11: 5060923782006 | B11: 79251 | C11: REFLO | D11: ADRIOXY | E11: ADRIOXY-M | F11: M | G11: M | H11: REFLO | I11: Playera tipo polo REFLO Adriatic Oxy/ Navy | J11: Ropa | K11: Playeras | M11: REFLO | P11: Azul | S11: Poliéster reciclado | T11: Playera tipo polo de golf REFLO modelo Adriatic en color Oxy/ Navy, confeccionado con materiales reciclados. Estilo ADRIOXY. | V11: PZS | W11: 53101600 | X11: https://i.ibb.co/NCvyXJJ/ADRIOXY.jpg | Y11: 26 | Z11: 1899 | AA11: =IF(AND(A11="", B11="", E11=""), "", IF(AB11="", "Válido", IF((LEN(AB11)-LEN(SUBSTITUTE(AB11,"; ","")))/2+1>(LEN(AB11)-LEN(SUBSTITUTE(AB11,"[Aviso]","")))/7, "Con Incidencias", "Válido"))) | AB11: =IF(AND(A11="", B11="", E11=""), "", TEXTJOIN("; ", TRUE, IF(OR(TRIM(A11&"")="", ISNUMBER(SEARCH("FALTA", A11))), "UPC faltante/inválido", ""), IF(AND(A11<>"", IFERROR(_xlfn.XMATCH(A11,$A$2:$A$653,0,1)<>_xlfn.XMATCH(A11,$A$2:$A$653,0,-1),FALSE)), "Código de barras duplicado", ""), IF(AND(E11<>"", COUNTIF($E$2:$E$653, E11)>1), "SKU duplicado", ""), IF(OR(J11="", J11=""), "[Aviso] División no capturada ()", IF(ISNA(MATCH(J11, Criterios!$A$123:$A$126, 0)), "División no válida", "")), IF(OR(K11="", K11=""), "[Aviso] Categoría no capturada ()", IF(ISNA(MATCH(K11, Criterios!$A$81:$A$120, 0)), "Categoría no válida", IF(AND(J11<>"", J11<>"", J11<>VLOOKUP(K11, Criterios!$A$81:$B$120, 2, FALSE)), "División no coincide con Categoría", ""))), IF(OR(L11="", L11=""), "[Aviso] Género no capturado ()", IF(ISNA(MATCH(L11, Criterios!$B$123:$B$127, 0)), "Género no válido", "")), IF(OR(N11="", N11=""), "[Aviso] Temporada no capturada ()", IF(ISNA(MATCH(N11, Criterios!$C$123:$C$128, 0)), "Temporada no válida", "")), IF(OR(O11="", O11=""), "[Aviso] Ciclo de vida no capturado ()", IF(ISNA(MATCH(O11, Criterios!$D$123:$D$124, 0)), "Ciclo de vida no válido", "")))) | AD11: 3 | AE11: REFLO ALMACEN (1); CONSIGNA REFLO (1) | AF11: 3 | AG11: Nuevo – NetSuite con existencia | AH11: Género no indicado en NetSuite; Composición: poliéster reciclado (validar % en etiqueta); Físico total NetSuite 3 ≠ suma por ubicación 2 | Revisión 29/09/2026: Marca REFLO fuera de lista Criterios; Campos sin respaldo: L, N, O, Q, U; Auditoría NetSuite 30/09/2026: llenado desde NetSuite [Z] | Homologación G1522 06/10/2026: Validador Shopify: WB: precio con IVA no termina en 9 | AI11: No | AK11: G1522ProductosTodosloscamposSandboxResults894.xlsx: fila 43910 [X,Y]; G1522_Extraccion_Articulos_NetSuite_2026-09-30.xlsx: fila 37584 [Z] | AL11: 26
A12: 5060923782013 | B12: 79252 | C12: REFLO | D12: ADRIOXY | E12: ADRIOXY-L | F12: L | G12: L | H12: REFLO | I12: Playera tipo polo REFLO Adriatic Oxy/ Navy | J12: Ropa | K12: Playeras | M12: REFLO | P12: Azul | S12: Poliéster reciclado | T12: Playera tipo polo de golf REFLO modelo Adriatic en color Oxy/ Navy, confeccionado con materiales reciclados. Estilo ADRIOXY. | V12: PZS | W12: 53101600 | X12: https://i.ibb.co/NCvyXJJ/ADRIOXY.jpg | Y12: 26 | Z12: 1899 | AA12: =IF(AND(A12="", B12="", E12=""), "", IF(AB12="", "Válido", IF((LEN(AB12)-LEN(SUBSTITUTE(AB12,"; ","")))/2+1>(LEN(AB12)-LEN(SUBSTITUTE(AB12,"[Aviso]","")))/7, "Con Incidencias", "Válido"))) | AB12: =IF(AND(A12="", B12="", E12=""), "", TEXTJOIN("; ", TRUE, IF(OR(TRIM(A12&"")="", ISNUMBER(SEARCH("FALTA", A12))), "UPC faltante/inválido", ""), IF(AND(A12<>"", IFERROR(_xlfn.XMATCH(A12,$A$2:$A$653,0,1)<>_xlfn.XMATCH(A12,$A$2:$A$653,0,-1),FALSE)), "Código de barras duplicado", ""), IF(AND(E12<>"", COUNTIF($E$2:$E$653, E12)>1), "SKU duplicado", ""), IF(OR(J12="", J12=""), "[Aviso] División no capturada ()", IF(ISNA(MATCH(J12, Criterios!$A$123:$A$126, 0)), "División no válida", "")), IF(OR(K12="", K12=""), "[Aviso] Categoría no capturada ()", IF(ISNA(MATCH(K12, Criterios!$A$81:$A$120, 0)), "Categoría no válida", IF(AND(J12<>"", J12<>"", J12<>VLOOKUP(K12, Criterios!$A$81:$B$120, 2, FALSE)), "División no coincide con Categoría", ""))), IF(OR(L12="", L12=""), "[Aviso] Género no capturado ()", IF(ISNA(MATCH(L12, Criterios!$B$123:$B$127, 0)), "Género no válido", "")), IF(OR(N12="", N12=""), "[Aviso] Temporada no capturada ()", IF(ISNA(MATCH(N12, Criterios!$C$123:$C$128, 0)), "Temporada no válida", "")), IF(OR(O12="", O12=""), "[Aviso] Ciclo de vida no capturado ()", IF(ISNA(MATCH(O12, Criterios!$D$123:$D$124, 0)), "Ciclo de vida no válido", "")))) | AD12: 9 | AE12: CONSIGNA REFLO (1); MUESTRAS REFLO (1); REFLO ALMACEN (3) | AF12: 8 | AG12: Nuevo – NetSuite con existencia | AH12: Género no indicado en NetSuite; Composición: poliéster reciclado (validar % en etiqueta); Físico total NetSuite 9 ≠ suma por ubicación 5 | Revisión 29/09/2026: Marca REFLO fuera de lista Criterios; Campos sin respaldo: L, N, O, Q, U; Auditoría NetSuite 30/09/2026: llenado desde NetSuite [Z] | Homologación G1522 06/10/2026: Validador Shopify: WB: precio con IVA no termina en 9 | AI12: No | AK12: G1522ProductosTodosloscamposSandboxResults894.xlsx: fila 43911 [X,Y]; G1522_Extraccion_Articulos_NetSuite_2026-09-30.xlsx: fila 37585 [Z] | AL12: 26
A13: 5060923782020 | B13: 79253 | C13: REFLO | D13: ADRIOXY | E13: ADRIOXY-XL | F13: XL | G13: XL | H13: REFLO | I13: Playera tipo polo REFLO Adriatic Oxy/ Navy | J13: Ropa | K13: Playeras | M13: REFLO | P13: Azul | S13: Poliéster reciclado | T13: Playera tipo polo de golf REFLO modelo Adriatic en color Oxy/ Navy, confeccionado con materiales reciclados. Estilo ADRIOXY. | V13: PZS | W13: 53101600 | X13: https://i.ibb.co/NCvyXJJ/ADRIOXY.jpg | Y13: 26 | Z13: 1899 | AA13: =IF(AND(A13="", B13="", E13=""), "", IF(AB13="", "Válido", IF((LEN(AB13)-LEN(SUBSTITUTE(AB13,"; ","")))/2+1>(LEN(AB13)-LEN(SUBSTITUTE(AB13,"[Aviso]","")))/7, "Con Incidencias", "Válido"))) | AB13: =IF(AND(A13="", B13="", E13=""), "", TEXTJOIN("; ", TRUE, IF(OR(TRIM(A13&"")="", ISNUMBER(SEARCH("FALTA", A13))), "UPC faltante/inválido", ""), IF(AND(A13<>"", IFERROR(_xlfn.XMATCH(A13,$A$2:$A$653,0,1)<>_xlfn.XMATCH(A13,$A$2:$A$653,0,-1),FALSE)), "Código de barras duplicado", ""), IF(AND(E13<>"", COUNTIF($E$2:$E$653, E13)>1), "SKU duplicado", ""), IF(OR(J13="", J13=""), "[Aviso] División no capturada ()", IF(ISNA(MATCH(J13, Criterios!$A$123:$A$126, 0)), "División no válida", "")), IF(OR(K13="", K13=""), "[Aviso] Categoría no capturada ()", IF(ISNA(MATCH(K13, Criterios!$A$81:$A$120, 0)), "Categoría no válida", IF(AND(J13<>"", J13<>"", J13<>VLOOKUP(K13, Criterios!$A$81:$B$120, 2, FALSE)), "División no coincide con Categoría", ""))), IF(OR(L13="", L13=""), "[Aviso] Género no capturado ()", IF(ISNA(MATCH(L13, Criterios!$B$123:$B$127, 0)), "Género no válido", "")), IF(OR(N13="", N13=""), "[Aviso] Temporada no capturada ()", IF(ISNA(MATCH(N13, Criterios!$C$123:$C$128, 0)), "Temporada no válida", "")), IF(OR(O13="", O13=""), "[Aviso] Ciclo de vida no capturado ()", IF(ISNA(MATCH(O13, Criterios!$D$123:$D$124, 0)), "Ciclo de vida no válido", "")))) | AD13: 12 | AE13: CONSIGNA REFLO (1); REFLO ALMACEN (5) | AF13: 12 | AG13: Nuevo – NetSuite con existencia | AH13: Género no indicado en NetSuite; Composición: poliéster reciclado (validar % en etiqueta); Físico total NetSuite 12 ≠ suma por ubicación 6 | Revisión 29/09/2026: Marca REFLO fuera de lista Criterios; Campos sin respaldo: L, N, O, Q, U; Auditoría NetSuite 30/09/2026: llenado desde NetSuite [Z] | Homologación G1522 06/10/2026: Validador Shopify: WB: precio con IVA no termina en 9 | AI13: No | AK13: G1522ProductosTodosloscamposSandboxResults894.xlsx: fila 43912 [X,Y]; G1522_Extraccion_Articulos_NetSuite_2026-09-30.xlsx: fila 37586 [Z] | AL13: 26
A14: 5060923782037 | B14: 79254 | C14: REFLO | D14: ADRIOXY | E14: ADRIOXY-XXL | F14: XXL | G14: XXL | H14: REFLO | I14: Playera tipo polo REFLO Adriatic Oxy/ Navy | J14: Ropa | K14: Playeras | M14: REFLO | P14: Azul | S14: Poliéster reciclado | T14: Playera tipo polo de golf REFLO modelo Adriatic en color Oxy/ Navy, confeccionado con materiales reciclados. Estilo ADRIOXY. | V14: PZS | W14: 53101600 | X14: https://i.ibb.co/NCvyXJJ/ADRIOXY.jpg | Y14: 26 | Z14: 1899 | AA14: =IF(AND(A14="", B14="", E14=""), "", IF(AB14="", "Válido", IF((LEN(AB14)-LEN(SUBSTITUTE(AB14,"; ","")))/2+1>(LEN(AB14)-LEN(SUBSTITUTE(AB14,"[Aviso]","")))/7, "Con Incidencias", "Válido"))) | AB14: =IF(AND(A14="", B14="", E14=""), "", TEXTJOIN("; ", TRUE, IF(OR(TRIM(A14&"")="", ISNUMBER(SEARCH("FALTA", A14))), "UPC faltante/inválido", ""), IF(AND(A14<>"", IFERROR(_xlfn.XMATCH(A14,$A$2:$A$653,0,1)<>_xlfn.XMATCH(A14,$A$2:$A$653,0,-1),FALSE)), "Código de barras duplicado", ""), IF(AND(E14<>"", COUNTIF($E$2:$E$653, E14)>1), "SKU duplicado", ""), IF(OR(J14="", J14=""), "[Aviso] División no capturada ()", IF(ISNA(MATCH(J14, Criterios!$A$123:$A$126, 0)), "División no válida", "")), IF(OR(K14="", K14=""), "[Aviso] Categoría no capturada ()", IF(ISNA(MATCH(K14, Criterios!$A$81:$A$120, 0)), "Categoría no válida", IF(AND(J14<>"", J14<>"", J14<>VLOOKUP(K14, Criterios!$A$81:$B$120, 2, FALSE)), "División no coincide con Categoría", ""))), IF(OR(L14="", L14=""), "[Aviso] Género no capturado ()", IF(ISNA(MATCH(L14, Criterios!$B$123:$B$127, 0)), "Género no válido", "")), IF(OR(N14="", N14=""), "[Aviso] Temporada no capturada ()", IF(ISNA(MATCH(N14, Criterios!$C$123:$C$128, 0)), "Temporada no válida", "")), IF(OR(O14="", O14=""), "[Aviso] Ciclo de vida no capturado ()", IF(ISNA(MATCH(O14, Criterios!$D$123:$D$124, 0)), "Ciclo de vida no válido", "")))) | AD14: 6 | AE14: REFLO ALMACEN (3) | AF14: 6 | AG14: Nuevo – NetSuite con existencia | AH14: Género no indicado en NetSuite; Composición: poliéster reciclado (validar % en etiqueta); Físico total NetSuite 6 ≠ suma por ubicación 3 | Revisión 29/09/2026: Marca REFLO fuera de lista Criterios; Campos sin respaldo: L, N, O, Q, U; Auditoría NetSuite 30/09/2026: llenado desde NetSuite [Z] | Homologación G1522 06/10/2026: Validador Shopify: WB: precio con IVA no termina en 9 | AI14: No | AK14: G1522ProductosTodosloscamposSandboxResults894.xlsx: fila 43913 [X,Y]; G1522_Extraccion_Articulos_NetSuite_2026-09-30.xlsx: fila 37587 [Z] | AL14: 26
A15: 5060923781993 | B15: 84421 | C15: REFLO | D15: ADRIOXY | E15: ADRIOXY-S | F15: S | G15: S | H15: REFLO | I15: Playera tipo polo REFLO Adriatic Oxy/Navy | J15: Ropa | K15: Playeras | M15: REFLO | P15: Azul | S15: Poliéster reciclado | T15: Playera tipo polo de golf REFLO modelo Adriatic en color Oxy/Navy, confeccionado con materiales reciclados. Estilo ADRIOXY. | V15: PZS | W15: 53101600 | X15: https://i.ibb.co/NCvyXJJ/ADRIOXY.jpg | Y15: 26 | Z15: 1899 | AA15: =IF(AND(A15="", B15="", E15=""), "", IF(AB15="", "Válido", IF((LEN(AB15)-LEN(SUBSTITUTE(AB15,"; ","")))/2+1>(LEN(AB15)-LEN(SUBSTITUTE(AB15,"[Aviso]","")))/7, "Con Incidencias", "Válido"))) | AB15: =IF(AND(A15="", B15="", E15=""), "", TEXTJOIN("; ", TRUE, IF(OR(TRIM(A15&"")="", ISNUMBER(SEARCH("FALTA", A15))), "UPC faltante/inválido", ""), IF(AND(A15<>"", IFERROR(_xlfn.XMATCH(A15,$A$2:$A$653,0,1)<>_xlfn.XMATCH(A15,$A$2:$A$653,0,-1),FALSE)), "Código de barras duplicado", ""), IF(AND(E15<>"", COUNTIF($E$2:$E$653, E15)>1), "SKU duplicado", ""), IF(OR(J15="", J15=""), "[Aviso] División no capturada ()", IF(ISNA(MATCH(J15, Criterios!$A$123:$A$126, 0)), "División no válida", "")), IF(OR(K15="", K15=""), "[Aviso] Categoría no capturada ()", IF(ISNA(MATCH(K15, Criterios!$A$81:$A$120, 0)), "Categoría no válida", IF(AND(J15<>"", J15<>"", J15<>VLOOKUP(K15, Criterios!$A$81:$B$120, 2, FALSE)), "División no coincide con Categoría", ""))), IF(OR(L15="", L15=""), "[Aviso] Género no capturado ()", IF(ISNA(MATCH(L15, Criterios!$B$123:$B$127, 0)), "Género no válido", "")), IF(OR(N15="", N15=""), "[Aviso] Temporada no capturada ()", IF(ISNA(MATCH(N15, Criterios!$C$123:$C$128, 0)), "Temporada no válida", "")), IF(OR(O15="", O15=""), "[Aviso] Ciclo de vida no capturado ()", IF(ISNA(MATCH(O15, Criterios!$D$123:$D$124, 0)), "Ciclo de vida no válido", "")))) | AD15: 8 | AE15: REFLO ALMACEN (2); CONSIGNA REFLO (2) | AF15: 8 | AG15: Nuevo – NetSuite con existencia | AH15: Género no indicado en NetSuite; Composición: poliéster reciclado (validar % en etiqueta); Físico total NetSuite 8 ≠ suma por ubicación 4 | Revisión 29/09/2026: Marca REFLO fuera de lista Criterios; Campos sin respaldo: L, N, O, Q, U; Auditoría NetSuite 30/09/2026: llenado desde NetSuite [Z] | Homologación G1522 06/10/2026: Validador Shopify: WB: precio con IVA no termina en 9 | AI15: No | AK15: G1522ProductosTodosloscamposSandboxResults894.xlsx: fila 43915 [X,Y]; G1522_Extraccion_Articulos_NetSuite_2026-09-30.xlsx: fila 39590 [Z] | AL15: 26
