Workbook

Sheet Escaneo Diario
A1: GRUPO QUINCE 22 | CONTROL DE INVENTARIOS Y CONTEO CÍCLICO DIARIO
A2: 📅 FECHA ACTUAL | C2: 📦 TOTAL ESCANEOS | E2: 🏷️ PRODUCTOS ÚNICOS | H2: 📊 TOTAL DE PIEZAS | J2: 🚀 ACCIÓN OPERATIVA
A3: =TODAY() | C3: =COUNTIF(C7:C1000, "<>") | E3: =IFERROR(__xludf.DUMMYFUNCTION("IFERROR(ROWS(UNIQUE(FILTER(D7:D1000, D7:D1000<>""""))), 0)"),0.0) | H3: =COUNTIF(C7:C1000, "<>") | J3: FINALIZAR ESCANEO
A4: Jornada en curso | C4: Registros capturados | E4: SKUs distintos | H4: Unidades contadas | J4: Asignar Folios y Archivar
A6: Fecha/Hora | B6: Ubicación/Rack | C6: UPC CODE | D6: SKU | E6: Marca | F6: Descripción | G6: División | H6: Categoría | I6: Talla / Size | J6: Alertas y Duplicados
D7: {=IF($C7="","",IFNA(_xlfn.XLOOKUP($C7,Productos!$A:$A,Productos!$E:$E,IFNA(_xlfn.XLOOKUP(TEXT($C7,"0"),Productos!$A:$A,Productos!$E:$E,IFNA(_xlfn.XLOOKUP(IFERROR(VALUE($C7),""),Productos!$A:$A,Productos!$E:$E,_xlfn.XLOOKUP($C7,Productos!$E:$E,Productos!$E:$E,"NO ENCONTRADO")),"NO ENCONTRADO")),"NO ENCONTRADO")),"NO ENCONTRADO"))} | E7: {=IF(OR($D7="",$D7="NO ENCONTRADO"),"",_xlfn.XLOOKUP($D7,Productos!$E:$E,Productos!$H:$H,""))} | F7: {=IF(OR($D7="",$D7="NO ENCONTRADO"),"",_xlfn.XLOOKUP($D7,Productos!$E:$E,Productos!$I:$I,""))} | G7: {=IF(OR($D7="",$D7="NO ENCONTRADO"),"",_xlfn.XLOOKUP($D7,Productos!$E:$E,Productos!$J:$J,""))} | H7: {=IF(OR($D7="",$D7="NO ENCONTRADO"),"",_xlfn.XLOOKUP($D7,Productos!$E:$E,Productos!$K:$K,""))} | I7: {=IF(OR($D7="",$D7="NO ENCONTRADO"),"",_xlfn.XLOOKUP($D7,Productos!$E:$E,Productos!$F:$F,""))} | J7: =IF($C7="","",IF($D7="NO ENCONTRADO",IF(COUNTIF($C$7:$C$1000,$C7)>1,"⚠️ No encontrado | Duplicado","⚠️ No encontrado"),IF(COUNTIF($C$7:$C$1000,$C7)>1,"⚠️ Duplicado","Verificado")))
D8: {=IF($C8="","",IFNA(_xlfn.XLOOKUP($C8,Productos!$A:$A,Productos!$E:$E,IFNA(_xlfn.XLOOKUP(TEXT($C8,"0"),Productos!$A:$A,Productos!$E:$E,IFNA(_xlfn.XLOOKUP(IFERROR(VALUE($C8),""),Productos!$A:$A,Productos!$E:$E,_xlfn.XLOOKUP($C8,Productos!$E:$E,Productos!$E:$E,"NO ENCONTRADO")),"NO ENCONTRADO")),"NO ENCONTRADO")),"NO ENCONTRADO"))} | E8: {=IF(OR($D8="",$D8="NO ENCONTRADO"),"",_xlfn.XLOOKUP($D8,Productos!$E:$E,Productos!$H:$H,""))} | F8: {=IF(OR($D8="",$D8="NO ENCONTRADO"),"",_xlfn.XLOOKUP($D8,Productos!$E:$E,Productos!$I:$I,""))} | G8: {=IF(OR($D8="",$D8="NO ENCONTRADO"),"",_xlfn.XLOOKUP($D8,Productos!$E:$E,Productos!$J:$J,""))} | H8: {=IF(OR($D8="",$D8="NO ENCONTRADO"),"",_xlfn.XLOOKUP($D8,Productos!$E:$E,Productos!$K:$K,""))} | I8: {=IF(OR($D8="",$D8="NO ENCONTRADO"),"",_xlfn.XLOOKUP($D8,Productos!$E:$E,Productos!$F:$F,""))} | J8: =IF($C8="","",IF($D8="NO ENCONTRADO",IF(COUNTIF($C$7:$C$1000,$C8)>1,"⚠️ No encontrado | Duplicado","⚠️ No encontrado"),IF(COUNTIF($C$7:$C$1000,$C8)>1,"⚠️ Duplicado","Verificado")))
D9: {=IF($C9="","",IFNA(_xlfn.XLOOKUP($C9,Productos!$A:$A,Productos!$E:$E,IFNA(_xlfn.XLOOKUP(TEXT($C9,"0"),Productos!$A:$A,Productos!$E:$E,IFNA(_xlfn.XLOOKUP(IFERROR(VALUE($C9),""),Productos!$A:$A,Productos!$E:$E,_xlfn.XLOOKUP($C9,Productos!$E:$E,Productos!$E:$E,"NO ENCONTRADO")),"NO ENCONTRADO")),"NO ENCONTRADO")),"NO ENCONTRADO"))} | E9: {=IF(OR($D9="",$D9="NO ENCONTRADO"),"",_xlfn.XLOOKUP($D9,Productos!$E:$E,Productos!$H:$H,""))} | F9: {=IF(OR($D9="",$D9="NO ENCONTRADO"),"",_xlfn.XLOOKUP($D9,Productos!$E:$E,Productos!$I:$I,""))} | G9: {=IF(OR($D9="",$D9="NO ENCONTRADO"),"",_xlfn.XLOOKUP($D9,Productos!$E:$E,Productos!$J:$J,""))} | H9: {=IF(OR($D9="",$D9="NO ENCONTRADO"),"",_xlfn.XLOOKUP($D9,Productos!$E:$E,Productos!$K:$K,""))} | I9: {=IF(OR($D9="",$D9="NO ENCONTRADO"),"",_xlfn.XLOOKUP($D9,Productos!$E:$E,Productos!$F:$F,""))} | J9: =IF($C9="","",IF($D9="NO ENCONTRADO",IF(COUNTIF($C$7:$C$1000,$C9)>1,"⚠️ No encontrado | Duplicado","⚠️ No encontrado"),IF(COUNTIF($C$7:$C$1000,$C9)>1,"⚠️ Duplicado","Verificado")))
D10: {=IF($C10="","",IFNA(_xlfn.XLOOKUP($C10,Productos!$A:$A,Productos!$E:$E,IFNA(_xlfn.XLOOKUP(TEXT($C10,"0"),Productos!$A:$A,Productos!$E:$E,IFNA(_xlfn.XLOOKUP(IFERROR(VALUE($C10),""),Productos!$A:$A,Productos!$E:$E,_xlfn.XLOOKUP($C10,Productos!$E:$E,Productos!$E:$E,"NO ENCONTRADO")),"NO ENCONTRADO")),"NO ENCONTRADO")),"NO ENCONTRADO"))} | E10: {=IF(OR($D10="",$D10="NO ENCONTRADO"),"",_xlfn.XLOOKUP($D10,Productos!$E:$E,Productos!$H:$H,""))} | F10: {=IF(OR($D10="",$D10="NO ENCONTRADO"),"",_xlfn.XLOOKUP($D10,Productos!$E:$E,Productos!$I:$I,""))} | G10: {=IF(OR($D10="",$D10="NO ENCONTRADO"),"",_xlfn.XLOOKUP($D10,Productos!$E:$E,Productos!$J:$J,""))} | H10: {=IF(OR($D10="",$D10="NO ENCONTRADO"),"",_xlfn.XLOOKUP($D10,Productos!$E:$E,Productos!$K:$K,""))} | I10: {=IF(OR($D10="",$D10="NO ENCONTRADO"),"",_xlfn.XLOOKUP($D10,Productos!$E:$E,Productos!$F:$F,""))} | J10: =IF($C10="","",IF($D10="NO ENCONTRADO",IF(COUNTIF($C$7:$C$1000,$C10)>1,"⚠️ No encontrado | Duplicado","⚠️ No encontrado"),IF(COUNTIF($C$7:$C$1000,$C10)>1,"⚠️ Duplicado","Verificado")))
D11: {=IF($C11="","",IFNA(_xlfn.XLOOKUP($C11,Productos!$A:$A,Productos!$E:$E,IFNA(_xlfn.XLOOKUP(TEXT($C11,"0"),Productos!$A:$A,Productos!$E:$E,IFNA(_xlfn.XLOOKUP(IFERROR(VALUE($C11),""),Productos!$A:$A,Productos!$E:$E,_xlfn.XLOOKUP($C11,Productos!$E:$E,Productos!$E:$E,"NO ENCONTRADO")),"NO ENCONTRADO")),"NO ENCONTRADO")),"NO ENCONTRADO"))} | E11: {=IF(OR($D11="",$D11="NO ENCONTRADO"),"",_xlfn.XLOOKUP($D11,Productos!$E:$E,Productos!$H:$H,""))} | F11: {=IF(OR($D11="",$D11="NO ENCONTRADO"),"",_xlfn.XLOOKUP($D11,Productos!$E:$E,Productos!$I:$I,""))} | G11: {=IF(OR($D11="",$D11="NO ENCONTRADO"),"",_xlfn.XLOOKUP($D11,Productos!$E:$E,Productos!$J:$J,""))} | H11: {=IF(OR($D11="",$D11="NO ENCONTRADO"),"",_xlfn.XLOOKUP($D11,Productos!$E:$E,Productos!$K:$K,""))} | I11: {=IF(OR($D11="",$D11="NO ENCONTRADO"),"",_xlfn.XLOOKUP($D11,Productos!$E:$E,Productos!$F:$F,""))} | J11: =IF($C11="","",IF($D11="NO ENCONTRADO",IF(COUNTIF($C$7:$C$1000,$C11)>1,"⚠️ No encontrado | Duplicado","⚠️ No encontrado"),IF(COUNTIF($C$7:$C$1000,$C11)>1,"⚠️ Duplicado","Verificado")))
D12: {=IF($C12="","",IFNA(_xlfn.XLOOKUP($C12,Productos!$A:$A,Productos!$E:$E,IFNA(_xlfn.XLOOKUP(TEXT($C12,"0"),Productos!$A:$A,Productos!$E:$E,IFNA(_xlfn.XLOOKUP(IFERROR(VALUE($C12),""),Productos!$A:$A,Productos!$E:$E,_xlfn.XLOOKUP($C12,Productos!$E:$E,Productos!$E:$E,"NO ENCONTRADO")),"NO ENCONTRADO")),"NO ENCONTRADO")),"NO ENCONTRADO"))} | E12: {=IF(OR($D12="",$D12="NO ENCONTRADO"),"",_xlfn.XLOOKUP($D12,Productos!$E:$E,Productos!$H:$H,""))} | F12: {=IF(OR($D12="",$D12="NO ENCONTRADO"),"",_xlfn.XLOOKUP($D12,Productos!$E:$E,Productos!$I:$I,""))} | G12: {=IF(OR($D12="",$D12="NO ENCONTRADO"),"",_xlfn.XLOOKUP($D12,Productos!$E:$E,Productos!$J:$J,""))} | H12: {=IF(OR($D12="",$D12="NO ENCONTRADO"),"",_xlfn.XLOOKUP($D12,Productos!$E:$E,Productos!$K:$K,""))} | I12: {=IF(OR($D12="",$D12="NO ENCONTRADO"),"",_xlfn.XLOOKUP($D12,Productos!$E:$E,Productos!$F:$F,""))} | J12: =IF($C12="","",IF($D12="NO ENCONTRADO",IF(COUNTIF($C$7:$C$1000,$C12)>1,"⚠️ No encontrado | Duplicado","⚠️ No encontrado"),IF(COUNTIF($C$7:$C$1000,$C12)>1,"⚠️ Duplicado","Verificado")))
D13: {=IF($C13="","",IFNA(_xlfn.XLOOKUP($C13,Productos!$A:$A,Productos!$E:$E,IFNA(_xlfn.XLOOKUP(TEXT($C13,"0"),Productos!$A:$A,Productos!$E:$E,IFNA(_xlfn.XLOOKUP(IFERROR(VALUE($C13),""),Productos!$A:$A,Productos!$E:$E,_xlfn.XLOOKUP($C13,Productos!$E:$E,Productos!$E:$E,"NO ENCONTRADO")),"NO ENCONTRADO")),"NO ENCONTRADO")),"NO ENCONTRADO"))} | E13: {=IF(OR($D13="",$D13="NO ENCONTRADO"),"",_xlfn.XLOOKUP($D13,Productos!$E:$E,Productos!$H:$H,""))} | F13: {=IF(OR($D13="",$D13="NO ENCONTRADO"),"",_xlfn.XLOOKUP($D13,Productos!$E:$E,Productos!$I:$I,""))} | G13: {=IF(OR($D13="",$D13="NO ENCONTRADO"),"",_xlfn.XLOOKUP($D13,Productos!$E:$E,Productos!$J:$J,""))} | H13: {=IF(OR($D13="",$D13="NO ENCONTRADO"),"",_xlfn.XLOOKUP($D13,Productos!$E:$E,Productos!$K:$K,""))} | I13: {=IF(OR($D13="",$D13="NO ENCONTRADO"),"",_xlfn.XLOOKUP($D13,Productos!$E:$E,Productos!$F:$F,""))} | J13: =IF($C13="","",IF($D13="NO ENCONTRADO",IF(COUNTIF($C$7:$C$1000,$C13)>1,"⚠️ No encontrado | Duplicado","⚠️ No encontrado"),IF(COUNTIF($C$7:$C$1000,$C13)>1,"⚠️ Duplicado","Verificado")))
D14: {=IF($C14="","",IFNA(_xlfn.XLOOKUP($C14,Productos!$A:$A,Productos!$E:$E,IFNA(_xlfn.XLOOKUP(TEXT($C14,"0"),Productos!$A:$A,Productos!$E:$E,IFNA(_xlfn.XLOOKUP(IFERROR(VALUE($C14),""),Productos!$A:$A,Productos!$E:$E,_xlfn.XLOOKUP($C14,Productos!$E:$E,Productos!$E:$E,"NO ENCONTRADO")),"NO ENCONTRADO")),"NO ENCONTRADO")),"NO ENCONTRADO"))} | E14: {=IF(OR($D14="",$D14="NO ENCONTRADO"),"",_xlfn.XLOOKUP($D14,Productos!$E:$E,Productos!$H:$H,""))} | F14: {=IF(OR($D14="",$D14="NO ENCONTRADO"),"",_xlfn.XLOOKUP($D14,Productos!$E:$E,Productos!$I:$I,""))} | G14: {=IF(OR($D14="",$D14="NO ENCONTRADO"),"",_xlfn.XLOOKUP($D14,Productos!$E:$E,Productos!$J:$J,""))} | H14: {=IF(OR($D14="",$D14="NO ENCONTRADO"),"",_xlfn.XLOOKUP($D14,Productos!$E:$E,Productos!$K:$K,""))} | I14: {=IF(OR($D14="",$D14="NO ENCONTRADO"),"",_xlfn.XLOOKUP($D14,Productos!$E:$E,Productos!$F:$F,""))} | J14: =IF($C14="","",IF($D14="NO ENCONTRADO",IF(COUNTIF($C$7:$C$1000,$C14)>1,"⚠️ No encontrado | Duplicado","⚠️ No encontrado"),IF(COUNTIF($C$7:$C$1000,$C14)>1,"⚠️ Duplicado","Verificado")))
D15: {=IF($C15="","",IFNA(_xlfn.XLOOKUP($C15,Productos!$A:$A,Productos!$E:$E,IFNA(_xlfn.XLOOKUP(TEXT($C15,"0"),Productos!$A:$A,Productos!$E:$E,IFNA(_xlfn.XLOOKUP(IFERROR(VALUE($C15),""),Productos!$A:$A,Productos!$E:$E,_xlfn.XLOOKUP($C15,Productos!$E:$E,Productos!$E:$E,"NO ENCONTRADO")),"NO ENCONTRADO")),"NO ENCONTRADO")),"NO ENCONTRADO"))} | E15: {=IF(OR($D15="",$D15="NO ENCONTRADO"),"",_xlfn.XLOOKUP($D15,Productos!$E:$E,Productos!$H:$H,""))} | F15: {=IF(OR($D15="",$D15="NO ENCONTRADO"),"",_xlfn.XLOOKUP($D15,Productos!$E:$E,Productos!$I:$I,""))} | G15: {=IF(OR($D15="",$D15="NO ENCONTRADO"),"",_xlfn.XLOOKUP($D15,Productos!$E:$E,Productos!$J:$J,""))} | H15: {=IF(OR($D15="",$D15="NO ENCONTRADO"),"",_xlfn.XLOOKUP($D15,Productos!$E:$E,Productos!$K:$K,""))} | I15: {=IF(OR($D15="",$D15="NO ENCONTRADO"),"",_xlfn.XLOOKUP($D15,Productos!$E:$E,Productos!$F:$F,""))} | J15: =IF($C15="","",IF($D15="NO ENCONTRADO",IF(COUNTIF($C$7:$C$1000,$C15)>1,"⚠️ No encontrado | Duplicado","⚠️ No encontrado"),IF(COUNTIF($C$7:$C$1000,$C15)>1,"⚠️ Duplicado","Verificado")))
D16: {=IF($C16="","",IFNA(_xlfn.XLOOKUP($C16,Productos!$A:$A,Productos!$E:$E,IFNA(_xlfn.XLOOKUP(TEXT($C16,"0"),Productos!$A:$A,Productos!$E:$E,IFNA(_xlfn.XLOOKUP(IFERROR(VALUE($C16),""),Productos!$A:$A,Productos!$E:$E,_xlfn.XLOOKUP($C16,Productos!$E:$E,Productos!$E:$E,"NO ENCONTRADO")),"NO ENCONTRADO")),"NO ENCONTRADO")),"NO ENCONTRADO"))} | E16: {=IF(OR($D16="",$D16="NO ENCONTRADO"),"",_xlfn.XLOOKUP($D16,Productos!$E:$E,Productos!$H:$H,""))} | F16: {=IF(OR($D16="",$D16="NO ENCONTRADO"),"",_xlfn.XLOOKUP($D16,Productos!$E:$E,Productos!$I:$I,""))} | G16: {=IF(OR($D16="",$D16="NO ENCONTRADO"),"",_xlfn.XLOOKUP($D16,Productos!$E:$E,Productos!$J:$J,""))} | H16: {=IF(OR($D16="",$D16="NO ENCONTRADO"),"",_xlfn.XLOOKUP($D16,Productos!$E:$E,Productos!$K:$K,""))} | I16: {=IF(OR($D16="",$D16="NO ENCONTRADO"),"",_xlfn.XLOOKUP($D16,Productos!$E:$E,Productos!$F:$F,""))} | J16: =IF($C16="","",IF($D16="NO ENCONTRADO",IF(COUNTIF($C$7:$C$1000,$C16)>1,"⚠️ No encontrado | Duplicado","⚠️ No encontrado"),IF(COUNTIF($C$7:$C$1000,$C16)>1,"⚠️ Duplicado","Verificado")))
D17: {=IF($C17="","",IFNA(_xlfn.XLOOKUP($C17,Productos!$A:$A,Productos!$E:$E,IFNA(_xlfn.XLOOKUP(TEXT($C17,"0"),Productos!$A:$A,Productos!$E:$E,IFNA(_xlfn.XLOOKUP(IFERROR(VALUE($C17),""),Productos!$A:$A,Productos!$E:$E,_xlfn.XLOOKUP($C17,Productos!$E:$E,Productos!$E:$E,"NO ENCONTRADO")),"NO ENCONTRADO")),"NO ENCONTRADO")),"NO ENCONTRADO"))} | E17: {=IF(OR($D17="",$D17="NO ENCONTRADO"),"",_xlfn.XLOOKUP($D17,Productos!$E:$E,Productos!$H:$H,""))} | F17: {=IF(OR($D17="",$D17="NO ENCONTRADO"),"",_xlfn.XLOOKUP($D17,Productos!$E:$E,Productos!$I:$I,""))} | G17: {=IF(OR($D17="",$D17="NO ENCONTRADO"),"",_xlfn.XLOOKUP($D17,Productos!$E:$E,Productos!$J:$J,""))} | H17: {=IF(OR($D17="",$D17="NO ENCONTRADO"),"",_xlfn.XLOOKUP($D17,Productos!$E:$E,Productos!$K:$K,""))} | I17: {=IF(OR($D17="",$D17="NO ENCONTRADO"),"",_xlfn.XLOOKUP($D17,Productos!$E:$E,Productos!$F:$F,""))} | J17: =IF($C17="","",IF($D17="NO ENCONTRADO",IF(COUNTIF($C$7:$C$1000,$C17)>1,"⚠️ No encontrado | Duplicado","⚠️ No encontrado"),IF(COUNTIF($C$7:$C$1000,$C17)>1,"⚠️ Duplicado","Verificado")))
D18: {=IF($C18="","",IFNA(_xlfn.XLOOKUP($C18,Productos!$A:$A,Productos!$E:$E,IFNA(_xlfn.XLOOKUP(TEXT($C18,"0"),Productos!$A:$A,Productos!$E:$E,IFNA(_xlfn.XLOOKUP(IFERROR(VALUE($C18),""),Productos!$A:$A,Productos!$E:$E,_xlfn.XLOOKUP($C18,Productos!$E:$E,Productos!$E:$E,"NO ENCONTRADO")),"NO ENCONTRADO")),"NO ENCONTRADO")),"NO ENCONTRADO"))} | E18: {=IF(OR($D18="",$D18="NO ENCONTRADO"),"",_xlfn.XLOOKUP($D18,Productos!$E:$E,Productos!$H:$H,""))} | F18: {=IF(OR($D18="",$D18="NO ENCONTRADO"),"",_xlfn.XLOOKUP($D18,Productos!$E:$E,Productos!$I:$I,""))} | G18: {=IF(OR($D18="",$D18="NO ENCONTRADO"),"",_xlfn.XLOOKUP($D18,Productos!$E:$E,Productos!$J:$J,""))} | H18: {=IF(OR($D18="",$D18="NO ENCONTRADO"),"",_xlfn.XLOOKUP($D18,Productos!$E:$E,Productos!$K:$K,""))} | I18: {=IF(OR($D18="",$D18="NO ENCONTRADO"),"",_xlfn.XLOOKUP($D18,Productos!$E:$E,Productos!$F:$F,""))} | J18: =IF($C18="","",IF($D18="NO ENCONTRADO",IF(COUNTIF($C$7:$C$1000,$C18)>1,"⚠️ No encontrado | Duplicado","⚠️ No encontrado"),IF(COUNTIF($C$7:$C$1000,$C18)>1,"⚠️ Duplicado","Verificado")))
... D1000: {=IF($C1000="","",IFNA(_xlfn.XLOOKUP($C1000,Productos!$A:$A,Productos!$E:$E,IFNA(_xlfn.XLOOKUP(TEXT($C1000,"0"),Productos!$A:$A,Productos!$E:$E,IFNA(_xlfn.XLOOKUP(IFERROR(VALUE($C1000),""),Productos!$A:$A,Productos!$E:$E,_xlfn.XLOOKUP($C1000,Productos!$E:$E,Productos!$E:$E,"NO ENCONTRADO")),"NO ENCONTRADO")),"NO ENCONTRADO")),"NO ENCONTRADO"))} | E1000: {=IF(OR($D1000="",$D1000="NO ENCONTRADO"),"",_xlfn.XLOOKUP($D1000,Productos!$E:$E,Productos!$H:$H,""))} | F1000: {=IF(OR($D1000="",$D1000="NO ENCONTRADO"),"",_xlfn.XLOOKUP($D1000,Productos!$E:$E,Productos!$I:$I,""))} | G1000: {=IF(OR($D1000="",$D1000="NO ENCONTRADO"),"",_xlfn.XLOOKUP($D1000,Productos!$E:$E,Productos!$J:$J,""))} | H1000: {=IF(OR($D1000="",$D1000="NO ENCONTRADO"),"",_xlfn.XLOOKUP($D1000,Productos!$E:$E,Productos!$K:$K,""))} | I1000: {=IF(OR($D1000="",$D1000="NO ENCONTRADO"),"",_xlfn.XLOOKUP($D1000,Productos!$E:$E,Productos!$F:$F,""))} | J1000: =IF($C1000="","",IF($D1000="NO ENCONTRADO",IF(COUNTIF($C$7:$C$1000,$C1000)>1,"⚠️ No encontrado | Duplicado","⚠️ No encontrado"),IF(COUNTIF($C$7:$C$1000,$C1000)>1,"⚠️ Duplicado","Verificado")))

Sheet Historial de Escaneos
A1: HISTORIAL Y BITÁCORA CONSOLIDADA DE CONTEOS CÍCLICOS - GRUPO QUINCE 22
A2: Registro histórico de auditorías, folios automáticos por ubicación y trazabilidad consolidada de marcas e inventario físico
A3: Fecha de Conteo | B3: Hora Registro | C3: Folio de Escaneo | D3: Ubicación / Rack | E3: Marcas Escaneadas (Todas) | F3: Total Piezas | G3: Auditor / Responsable | H3: Dictamen de Auditoría | I3: Alertas de Modificación / Incidencias

Sheet Escaneos
A1: Folio de Escaneo | B1: Fecha / Hora | C1: Ubicación / Rack | D1: UPC CODE | E1: SKU | F1: Marca | G1: Descripción | H1: Categoría | I1: Talla / Size | J1: Piezas Contadas | K1: Auditor / Responsable | L1: Estado de Conteo | M1: Detalle de Modificaciones / Alertas

Sheet Configuración
A1: CONFIGURACIÓN DEL SISTEMA Y CATÁLOGOS MAESTROS - GRUPO QUINCE 22
A2: Catálogos oficiales para validación de datos y listas desplegables del conteo cíclico diario
A3: Ubicaciones / Racks | B3: Marcas | C3: Categorías | D3: Tallas / Sizes | E3: Auditores / Operadores | F3: Estado de Conteo | H3: Ubicaciones NetSuite (Hoja a Revisar) | I3: SKUs con stock | J3: Piezas en sistema
A4: Pasillo A - Racks Principales | B4: 1522 Original | C4: Playeras | D4: XS | E4: Jesús Fregoso | F4: Verificado | H4: Almacenes G1522 | I4: {=_xlfn.XLOOKUP($H4,Criterios!$G$6:$G$200,Criterios!I$6:I$200,"")} | J4: {=_xlfn.XLOOKUP($H4,Criterios!$G$6:$G$200,Criterios!J$6:J$200,"")}
A5: Pasillo B - Estantería Media | B5: Urban Trend | C5: Pantalones | D5: S | E5: Carlos Morales | F5: Con Discrepancia | H5: AMAZON | I5: {=_xlfn.XLOOKUP($H5,Criterios!$G$6:$G$200,Criterios!I$6:I$200,"")} | J5: {=_xlfn.XLOOKUP($H5,Criterios!$G$6:$G$200,Criterios!J$6:J$200,"")}
A6: Pasillo C - Calzado y Confección | B6: Denim Co. | C6: Sudaderas | D6: M | E6: Andrea Valenzuela | F6: Pendiente | H6: ARIAT CHIHUAHUA | I6: {=_xlfn.XLOOKUP($H6,Criterios!$G$6:$G$200,Criterios!I$6:I$200,"")} | J6: {=_xlfn.XLOOKUP($H6,Criterios!$G$6:$G$200,Criterios!J$6:J$200,"")}
A7: Pasillo D - Accesorios | B7: Active Wear | C7: Chamarras | D7: L | E7: Luis Fernández | F7: Revisión Requerida | H7: ARIAT OUTLET GDL | I7: {=_xlfn.XLOOKUP($H7,Criterios!$G$6:$G$200,Criterios!I$6:I$200,"")} | J7: {=_xlfn.XLOOKUP($H7,Criterios!$G$6:$G$200,Criterios!J$6:J$200,"")}
A8: Pasillo E - Devoluciones | B8: Casual Basics | C8: Gorras | D8: XL | E8: Mariana Garza | H8: ARIAT PLAZA SAN LUIS | I8: {=_xlfn.XLOOKUP($H8,Criterios!$G$6:$G$200,Criterios!I$6:I$200,"")} | J8: {=_xlfn.XLOOKUP($H8,Criterios!$G$6:$G$200,Criterios!J$6:J$200,"")}
A9: Bodega Central - Tarimas | B9: Signature 1522 | C9: Camisas | D9: XXL | E9: Roberto Méndez | H9: ARIAT SAN NICOLAS NL | I9: {=_xlfn.XLOOKUP($H9,Criterios!$G$6:$G$200,Criterios!I$6:I$200,"")} | J9: {=_xlfn.XLOOKUP($H9,Criterios!$G$6:$G$200,Criterios!J$6:J$200,"")}
A10: Zona de Picking 1 | B10: Premium Line | C10: Calzado | D10: 28x32 | E10: Sofía Castro | H10: B25 CEDIS | I10: {=_xlfn.XLOOKUP($H10,Criterios!$G$6:$G$200,Criterios!I$6:I$200,"")} | J10: {=_xlfn.XLOOKUP($H10,Criterios!$G$6:$G$200,Criterios!J$6:J$200,"")}
A11: Zona de Recepción | B11: Vintage Republic | C11: Accesorios | D11: 30x32 | E11: Miguel Ángel Ruiz | H11: B25 STETSON.MX | I11: {=_xlfn.XLOOKUP($H11,Criterios!$G$6:$G$200,Criterios!I$6:I$200,"")} | J11: {=_xlfn.XLOOKUP($H11,Criterios!$G$6:$G$200,Criterios!J$6:J$200,"")}
A12: Almacén General - Cuarentena | B12: Essentials | C12: Ropa Deportiva | D12: 32x32 | E12: Diana Navarro | H12: B25 WB MERCADO LIBRE | I12: {=_xlfn.XLOOKUP($H12,Criterios!$G$6:$G$200,Criterios!I$6:I$200,"")} | J12: {=_xlfn.XLOOKUP($H12,Criterios!$G$6:$G$200,Criterios!J$6:J$200,"")}
A13: Mesa de Empaque | B13: Colección Especial | C13: Ropa Interior | D13: 34x32 | E13: Pedro Gómez | H13: B25 WESTERN BROTHERS.MX | I13: {=_xlfn.XLOOKUP($H13,Criterios!$G$6:$G$200,Criterios!I$6:I$200,"")} | J13: {=_xlfn.XLOOKUP($H13,Criterios!$G$6:$G$200,Criterios!J$6:J$200,"")}
A14: Área de Devoluciones | B14: Edición Limitada | C14: Calcetería | D14: UNITALLA | E14: Laura Sánchez | H14: CAPSLAB Warehouse | I14: {=_xlfn.XLOOKUP($H14,Criterios!$G$6:$G$200,Criterios!I$6:I$200,"")} | J14: {=_xlfn.XLOOKUP($H14,Criterios!$G$6:$G$200,Criterios!J$6:J$200,"")}
A15: J1-L1-01 | B15: Stetson | C15: Jeans | D15: 29 x 32 | H15: CL Muestras | I15: {=_xlfn.XLOOKUP($H15,Criterios!$G$6:$G$200,Criterios!I$6:I$200,"")} | J15: {=_xlfn.XLOOKUP($H15,Criterios!$G$6:$G$200,Criterios!J$6:J$200,"")}
A16: Almacenes G1522 | B16: Ariat | C16: Denim | D16: 30 x 32 | H16: CL POS | I16: {=_xlfn.XLOOKUP($H16,Criterios!$G$6:$G$200,Criterios!I$6:I$200,"")} | J16: {=_xlfn.XLOOKUP($H16,Criterios!$G$6:$G$200,Criterios!J$6:J$200,"")}
A17: AMAZON | B17: CAPSLAB | C17: Ropa | D17: 31 x 32 | H17: CONSIGNA REFLO | I17: {=_xlfn.XLOOKUP($H17,Criterios!$G$6:$G$200,Criterios!I$6:I$200,"")} | J17: {=_xlfn.XLOOKUP($H17,Criterios!$G$6:$G$200,Criterios!J$6:J$200,"")}
A18: ARIAT CHIHUAHUA | B18: Denver | D18: 32 x 34 | H18: CONSIGNAS | I18: {=_xlfn.XLOOKUP($H18,Criterios!$G$6:$G$200,Criterios!I$6:I$200,"")} | J18: {=_xlfn.XLOOKUP($H18,Criterios!$G$6:$G$200,Criterios!J$6:J$200,"")}
A19: ARIAT OUTLET GDL | B19: Generico | D19: 33 x 32 | H19: DEPARTAMENTAL | I19: {=_xlfn.XLOOKUP($H19,Criterios!$G$6:$G$200,Criterios!I$6:I$200,"")} | J19: {=_xlfn.XLOOKUP($H19,Criterios!$G$6:$G$200,Criterios!J$6:J$200,"")}
A20: ARIAT PLAZA SAN LUIS | B20: Happy Socks | D20: 34 x 34 | H20: ECOMMERCE | I20: {=_xlfn.XLOOKUP($H20,Criterios!$G$6:$G$200,Criterios!I$6:I$200,"")} | J20: {=_xlfn.XLOOKUP($H20,Criterios!$G$6:$G$200,Criterios!J$6:J$200,"")}
A21: ARIAT SAN NICOLAS NL | B21: Montana West | D21: 34 x 36 | H21: ENGLISH REP | I21: {=_xlfn.XLOOKUP($H21,Criterios!$G$6:$G$200,Criterios!I$6:I$200,"")} | J21: {=_xlfn.XLOOKUP($H21,Criterios!$G$6:$G$200,Criterios!J$6:J$200,"")}
A22: B25 CEDIS | B22: REFLO | D22: 36 x 32 | H22: EVENTOS (CONSIGNA) | I22: {=_xlfn.XLOOKUP($H22,Criterios!$G$6:$G$200,Criterios!I$6:I$200,"")} | J22: {=_xlfn.XLOOKUP($H22,Criterios!$G$6:$G$200,Criterios!J$6:J$200,"")}
A23: B25 STETSON.MX | B23: Ranch & Corral | D23: 36 x 34 | H23: Fixtures & MKT | I23: {=_xlfn.XLOOKUP($H23,Criterios!$G$6:$G$200,Criterios!I$6:I$200,"")} | J23: {=_xlfn.XLOOKUP($H23,Criterios!$G$6:$G$200,Criterios!J$6:J$200,"")}
A24: B25 WB MERCADO LIBRE | B24: Tru Western | D24: 38 x 32 | H24: FULL MELI | I24: {=_xlfn.XLOOKUP($H24,Criterios!$G$6:$G$200,Criterios!I$6:I$200,"")} | J24: {=_xlfn.XLOOKUP($H24,Criterios!$G$6:$G$200,Criterios!J$6:J$200,"")}
A25: B25 WESTERN BROTHERS.MX | B25: Willow Lane | D25: 32 x 32 | H25: G1522 Defectos | I25: {=_xlfn.XLOOKUP($H25,Criterios!$G$6:$G$200,Criterios!I$6:I$200,"")} | J25: {=_xlfn.XLOOKUP($H25,Criterios!$G$6:$G$200,Criterios!J$6:J$200,"")}
A26: CAPSLAB Warehouse | B26: Wrangler | D26: 34 x 32 | H26: G1522 Lost | I26: {=_xlfn.XLOOKUP($H26,Criterios!$G$6:$G$200,Criterios!I$6:I$200,"")} | J26: {=_xlfn.XLOOKUP($H26,Criterios!$G$6:$G$200,Criterios!J$6:J$200,"")}
A27: CL Muestras | H27: G1522 QA Hold | I27: {=_xlfn.XLOOKUP($H27,Criterios!$G$6:$G$200,Criterios!I$6:I$200,"")} | J27: {=_xlfn.XLOOKUP($H27,Criterios!$G$6:$G$200,Criterios!J$6:J$200,"")}
A28: CL POS | H28: GENERAL | I28: {=_xlfn.XLOOKUP($H28,Criterios!$G$6:$G$200,Criterios!I$6:I$200,"")} | J28: {=_xlfn.XLOOKUP($H28,Criterios!$G$6:$G$200,Criterios!J$6:J$200,"")}
A29: CONSIGNA REFLO | H29: HAPPY SOCKS | I29: {=_xlfn.XLOOKUP($H29,Criterios!$G$6:$G$200,Criterios!I$6:I$200,"")} | J29: {=_xlfn.XLOOKUP($H29,Criterios!$G$6:$G$200,Criterios!J$6:J$200,"")}
A30: CONSIGNAS | H30: HS MERCADO LIBRE | I30: {=_xlfn.XLOOKUP($H30,Criterios!$G$6:$G$200,Criterios!I$6:I$200,"")} | J30: {=_xlfn.XLOOKUP($H30,Criterios!$G$6:$G$200,Criterios!J$6:J$200,"")}
A31: DEPARTAMENTAL | H31: KEY ACCOUNTS | I31: {=_xlfn.XLOOKUP($H31,Criterios!$G$6:$G$200,Criterios!I$6:I$200,"")} | J31: {=_xlfn.XLOOKUP($H31,Criterios!$G$6:$G$200,Criterios!J$6:J$200,"")}
A32: ECOMMERCE | H32: LIVERPOOL MKP | I32: {=_xlfn.XLOOKUP($H32,Criterios!$G$6:$G$200,Criterios!I$6:I$200,"")} | J32: {=_xlfn.XLOOKUP($H32,Criterios!$G$6:$G$200,Criterios!J$6:J$200,"")}
A33: ENGLISH REP | H33: Mercado libre | I33: {=_xlfn.XLOOKUP($H33,Criterios!$G$6:$G$200,Criterios!I$6:I$200,"")} | J33: {=_xlfn.XLOOKUP($H33,Criterios!$G$6:$G$200,Criterios!J$6:J$200,"")}
A34: EVENTOS (CONSIGNA) | H34: MUESTRAS & EXPO | I34: {=_xlfn.XLOOKUP($H34,Criterios!$G$6:$G$200,Criterios!I$6:I$200,"")} | J34: {=_xlfn.XLOOKUP($H34,Criterios!$G$6:$G$200,Criterios!J$6:J$200,"")}
A35: Fixtures & MKT | H35: MUESTRAS REFLO | I35: {=_xlfn.XLOOKUP($H35,Criterios!$G$6:$G$200,Criterios!I$6:I$200,"")} | J35: {=_xlfn.XLOOKUP($H35,Criterios!$G$6:$G$200,Criterios!J$6:J$200,"")}
A36: FULL MELI | H36: Nogales Store | I36: {=_xlfn.XLOOKUP($H36,Criterios!$G$6:$G$200,Criterios!I$6:I$200,"")} | J36: {=_xlfn.XLOOKUP($H36,Criterios!$G$6:$G$200,Criterios!J$6:J$200,"")}
A37: G1522 Defectos | H37: Plaza del Sol Store | I37: {=_xlfn.XLOOKUP($H37,Criterios!$G$6:$G$200,Criterios!I$6:I$200,"")} | J37: {=_xlfn.XLOOKUP($H37,Criterios!$G$6:$G$200,Criterios!J$6:J$200,"")}
A38: G1522 Lost | H38: POTRILLOS | I38: {=_xlfn.XLOOKUP($H38,Criterios!$G$6:$G$200,Criterios!I$6:I$200,"")} | J38: {=_xlfn.XLOOKUP($H38,Criterios!$G$6:$G$200,Criterios!J$6:J$200,"")}
... A52: PUNTO DE VENTA | H52: ZONA SUR | I52: {=_xlfn.XLOOKUP($H52,Criterios!$G$6:$G$200,Criterios!I$6:I$200,"")} | J52: {=_xlfn.XLOOKUP($H52,Criterios!$G$6:$G$200,Criterios!J$6:J$200,"")}
A53: Punto de venta HS
...

Sheet Productos
A1: Código de barras | B1: Identificador interno | C1: Marca principal | D1: WB N.º de estilo | E1: WB SKU | F1: WB Talla | G1: WB Talla de EE. UU. | H1: WB Marca | I1: WB Descripcion | J1: WB División | K1: WB Categoría | L1: WB Género | M1: WB Licencia | N1: WB Temporada | O1: WB Ciclo de vida | P1: WB Color | Q1: WB Fit | R1: WB Silueta | S1: WB Composición | T1: WB Descripción larga | U1: WB País de origen | V1: Unidad | W1: SAT Clave de producto | X1: Enlace de imagen | Y1: Precio de compra | Z1: Precio de venta | AA1: Estatus de Validación | AB1: Detalle de Discrepancias | AC1: 🔍 Panel de Duplicados | AD1: Stock Sistema NetSuite | AE1: Ubicaciones con stock (NetSuite) | AF1: Disponible NetSuite | AG1: Origen del registro | AH1: Notas de enriquecimiento / revisión | AI1: ¿Alguna ubicación en negativo? | AJ1: Ubicaciones con existencia negativa | AK1: Fuentes de consulta | AL1: Precio compra vigente | AM1: Precio venta vigente | AN1: 📍 Ubicación en plataformas (Plataforma + Marca) | AO1: Stock Shopify Stetson México | AP1: Stock Shopify Western Brothers | AQ1: Stock Odoo Universal Unique Brands | AR1: Ubicaciones con stock (plataformas)
A2: 182900115001 | B2: 111788 | C2: Multimarca | D2: WL0001 | E2: WL0001-UNI | F2: Talla única | G2: One Size | H2: Generico | I2: Duffle de piel oversize | J2: Accesorios | K2: Equipaje | L2: Unisex | M2: Generico | N2: SS26 | O2: Seasonal | S2: 100% Piel | T2: Duffle de piel oversize | U2: Estados Unidos | V2: PZS | W2: 53121500 | X2: https://cdn.shopify.com/s/files/1/0774/1849/6185/files/WhatsAppImage2026-06-25at4.38.48PM_d84fc7e2-035d-4cbc-b9fd-349607a00a5c.jpg?v=1782523706 | Y2: 2275 | Z2: 6499 | AA2: =IF(AND(A2="", B2="", E2=""), "", IF(AB2="", "Válido", IF((LEN(AB2)-LEN(SUBSTITUTE(AB2,"; ","")))/2+1>(LEN(AB2)-LEN(SUBSTITUTE(AB2,"[Aviso]","")))/7, "Con Incidencias", "Válido"))) | AB2: =IF(AND(A2="", B2="", E2=""), "", TEXTJOIN("; ", TRUE, IF(OR(TRIM(A2&"")="", ISNUMBER(SEARCH("FALTA", A2))), "UPC faltante/inválido", ""), IF(AND(A2<>"", IFERROR(_xlfn.XMATCH(A2,$A$2:$A$12,0,1)<>_xlfn.XMATCH(A2,$A$2:$A$12,0,-1),FALSE)), "Código de barras duplicado", ""), IF(AND(E2<>"", COUNTIF($E$2:$E$12, E2)>1), "SKU duplicado", ""), IF(OR(J2="", J2=""), "[Aviso] División no capturada ()", IF(ISNA(MATCH(J2, Criterios!$A$123:$A$126, 0)), "División no válida", "")), IF(OR(K2="", K2=""), "[Aviso] Categoría no capturada ()", IF(ISNA(MATCH(K2, Criterios!$A$81:$A$120, 0)), "Categoría no válida", IF(AND(J2<>"", J2<>"", J2<>VLOOKUP(K2, Criterios!$A$81:$B$120, 2, FALSE)), "División no coincide con Categoría", ""))), IF(OR(L2="", L2=""), "[Aviso] Género no capturado ()", IF(ISNA(MATCH(L2, Criterios!$B$123:$B$127, 0)), "Género no válido", "")), IF(OR(N2="", N2=""), "[Aviso] Temporada no capturada ()", IF(ISNA(MATCH(N2, Criterios!$C$123:$C$128, 0)), "Temporada no válida", "")), IF(OR(O2="", O2=""), "[Aviso] Ciclo de vida no capturado ()", IF(ISNA(MATCH(O2, Criterios!$D$123:$D$124, 0)), "Ciclo de vida no válido", "")))) | AD2: 1 | AE2: WB OUTLET LERMA: 1 | AF2: 1 | AG2: Nuevo – NetSuite con existencia | AH2: Color por validar; Clave SAT por validar | Revisión 29/09/2026: Campos sin respaldo: P, X; Auditoría NetSuite 30/09/2026: llenado desde NetSuite [V,Z,T] | 01/10/2026: complementado desde Shopify Western Brothers (match por código de barras): WB Fit, WB Silueta, Enlace de imagen | 01/10/2026: Shopify Western Brothers trae Género «Mujer» — se conservó el valor de Productos | Homologación G1522 06/10/2026: WB País de origen: «USA» → «Estados Unidos» (Corrección aplicada) · Validación G1522: Dígito de control del código de barras inválido · Validador Shopify: WB: precio con IVA no termina en 9 | AI2: No | AK2: ProductosCatalogoEstandar907.xlsx: fila 6173 [N,O,S,U,W,Y]; G1522_Extraccion_Articulos_NetSuite_2026-09-30.xlsx: fila 59390 [V,Z,T] | Shopify WB: producto 8577838809273 / variante 47786243260601 | AL2: 2275 | AM2: 6499 | AN2: Shopify Western Brothers | AP2: 1 | AR2: Shopify Western Brothers › Western Brothers Outlet Lerma: 1
A3: 182900115002 | B3: 111796 | C3: Multimarca | D3: WL0002 | E3: WL0002-UNI | F3: Talla única | G3: One Size | H3: Generico | I3: Mochila pelo de res/repujada | J3: Accesorios | K3: Mochilas | L3: Unisex | M3: Generico | N3: SS26 | O3: Seasonal | S3: 100% Piel | T3: Mochila pelo de res/repujada | U3: Estados Unidos | V3: PZS | W3: 53121603 | X3: https://cdn.shopify.com/s/files/1/0774/1849/6185/files/WhatsAppImage2026-06-25at4.38.49PM_1.jpg?v=1782523678 | Y3: 1662.5 | Z3: 4050.8621 | AA3: =IF(AND(A3="", B3="", E3=""), "", IF(AB3="", "Válido", IF((LEN(AB3)-LEN(SUBSTITUTE(AB3,"; ","")))/2+1>(LEN(AB3)-LEN(SUBSTITUTE(AB3,"[Aviso]","")))/7, "Con Incidencias", "Válido"))) | AB3: =IF(AND(A3="", B3="", E3=""), "", TEXTJOIN("; ", TRUE, IF(OR(TRIM(A3&"")="", ISNUMBER(SEARCH("FALTA", A3))), "UPC faltante/inválido", ""), IF(AND(A3<>"", IFERROR(_xlfn.XMATCH(A3,$A$2:$A$12,0,1)<>_xlfn.XMATCH(A3,$A$2:$A$12,0,-1),FALSE)), "Código de barras duplicado", ""), IF(AND(E3<>"", COUNTIF($E$2:$E$12, E3)>1), "SKU duplicado", ""), IF(OR(J3="", J3=""), "[Aviso] División no capturada ()", IF(ISNA(MATCH(J3, Criterios!$A$123:$A$126, 0)), "División no válida", "")), IF(OR(K3="", K3=""), "[Aviso] Categoría no capturada ()", IF(ISNA(MATCH(K3, Criterios!$A$81:$A$120, 0)), "Categoría no válida", IF(AND(J3<>"", J3<>"", J3<>VLOOKUP(K3, Criterios!$A$81:$B$120, 2, FALSE)), "División no coincide con Categoría", ""))), IF(OR(L3="", L3=""), "[Aviso] Género no capturado ()", IF(ISNA(MATCH(L3, Criterios!$B$123:$B$127, 0)), "Género no válido", "")), IF(OR(N3="", N3=""), "[Aviso] Temporada no capturada ()", IF(ISNA(MATCH(N3, Criterios!$C$123:$C$128, 0)), "Temporada no válida", "")), IF(OR(O3="", O3=""), "[Aviso] Ciclo de vida no capturado ()", IF(ISNA(MATCH(O3, Criterios!$D$123:$D$124, 0)), "Ciclo de vida no válido", "")))) | AD3: 7 | AE3: WB OUTLET LERMA: 7 | AF3: 7 | AG3: Nuevo – NetSuite con existencia | AH3: Color por validar | Revisión 29/09/2026: Campos sin respaldo: P, X; Auditoría NetSuite 30/09/2026: llenado desde NetSuite [V,Y,T] | 01/10/2026: complementado desde Shopify Western Brothers (match por código de barras): WB Fit, WB Silueta, Enlace de imagen | 01/10/2026: Shopify Western Brothers trae Género «Mujer» — se conservó el valor de Productos | Homologación G1522 06/10/2026: WB País de origen: «USA» → «Estados Unidos» (Corrección aplicada) · Validación G1522: Dígito de control del código de barras inválido | AI3: No | AK3: ProductosCatalogoEstandar907.xlsx: fila 6174 [N,O,S,U,Y]; G1522_Extraccion_Articulos_NetSuite_2026-09-30.xlsx: fila 59398 [V,Y,T] | Shopify WB: producto 8577838940345 / variante 47786243391673 | AL3: 1662.5 | AM3: 4699 | AN3: Shopify Western Brothers | AP3: 7 | AR3: Shopify Western Brothers › Western Brothers Outlet Lerma: 7
A4: 182900115003 | B4: 111789 | C4: Multimarca | D4: WL0003 | E4: WL0003-UNI | F4: Talla única | G4: One Size | H4: Generico | I4: Duffle pelo de res/repujado | J4: Accesorios | K4: Equipaje | L4: Unisex | M4: Generico | N4: SS26 | O4: Seasonal | S4: 100% Piel | T4: Duffle pelo de res/repujado | U4: Estados Unidos | V4: PZS | W4: 53121500 | X4: https://cdn.shopify.com/s/files/1/0774/1849/6185/files/WhatsAppImage2026-06-25at4.38.46PM_2.jpg?v=1782523607 | Y4: 1925 | Z4: 5499 | AA4: =IF(AND(A4="", B4="", E4=""), "", IF(AB4="", "Válido", IF((LEN(AB4)-LEN(SUBSTITUTE(AB4,"; ","")))/2+1>(LEN(AB4)-LEN(SUBSTITUTE(AB4,"[Aviso]","")))/7, "Con Incidencias", "Válido"))) | AB4: =IF(AND(A4="", B4="", E4=""), "", TEXTJOIN("; ", TRUE, IF(OR(TRIM(A4&"")="", ISNUMBER(SEARCH("FALTA", A4))), "UPC faltante/inválido", ""), IF(AND(A4<>"", IFERROR(_xlfn.XMATCH(A4,$A$2:$A$12,0,1)<>_xlfn.XMATCH(A4,$A$2:$A$12,0,-1),FALSE)), "Código de barras duplicado", ""), IF(AND(E4<>"", COUNTIF($E$2:$E$12, E4)>1), "SKU duplicado", ""), IF(OR(J4="", J4=""), "[Aviso] División no capturada ()", IF(ISNA(MATCH(J4, Criterios!$A$123:$A$126, 0)), "División no válida", "")), IF(OR(K4="", K4=""), "[Aviso] Categoría no capturada ()", IF(ISNA(MATCH(K4, Criterios!$A$81:$A$120, 0)), "Categoría no válida", IF(AND(J4<>"", J4<>"", J4<>VLOOKUP(K4, Criterios!$A$81:$B$120, 2, FALSE)), "División no coincide con Categoría", ""))), IF(OR(L4="", L4=""), "[Aviso] Género no capturado ()", IF(ISNA(MATCH(L4, Criterios!$B$123:$B$127, 0)), "Género no válido", "")), IF(OR(N4="", N4=""), "[Aviso] Temporada no capturada ()", IF(ISNA(MATCH(N4, Criterios!$C$123:$C$128, 0)), "Temporada no válida", "")), IF(OR(O4="", O4=""), "[Aviso] Ciclo de vida no capturado ()", IF(ISNA(MATCH(O4, Criterios!$D$123:$D$124, 0)), "Ciclo de vida no válido", "")))) | AD4: 4 | AE4: WB OUTLET LERMA: 4 | AF4: 4 | AG4: Nuevo – NetSuite con existencia | AH4: Color por validar; Clave SAT por validar | Revisión 29/09/2026: Campos sin respaldo: P, X; Auditoría NetSuite 30/09/2026: llenado desde NetSuite [V,Z,T] | 01/10/2026: complementado desde Shopify Western Brothers (match por código de barras): WB Fit, WB Silueta, Enlace de imagen | 01/10/2026: Shopify Western Brothers trae Género «Mujer» — se conservó el valor de Productos | Homologación G1522 06/10/2026: WB País de origen: «USA» → «Estados Unidos» (Corrección aplicada) · Validación G1522: Dígito de control del código de barras inválido · Validador Shopify: WB: precio con IVA no termina en 9 | AI4: No | AK4: ProductosCatalogoEstandar907.xlsx: fila 6175 [N,O,S,U,W,Y]; G1522_Extraccion_Articulos_NetSuite_2026-09-30.xlsx: fila 59391 [V,Z,T] | Shopify WB: producto 8577839038649 / variante 47786243686585 | AL4: 1925 | AM4: 5499 | AN4: Shopify Western Brothers | AP4: 4 | AR4: Shopify Western Brothers › Western Brothers Outlet Lerma: 4
A5: 182900115004 | B5: 111795 | C5: Multimarca | D5: WL0004 | E5: WL0004-UNI | F5: Talla única | G5: One Size | H5: Generico | I5: Monedero pelo de res | J5: Accesorios | K5: Carteras | L5: Unisex | M5: Generico | N5: SS26 | O5: Seasonal | S5: 100% Piel | T5: Monedero pelo de res | U5: Estados Unidos | V5: PZS | W5: 53121700 | X5: https://cdn.shopify.com/s/files/1/0774/1849/6185/files/WhatsAppImage2026-06-25at4.38.43PM_1_4b25f101-a6a4-46bb-bb06-17667f4ea190.jpg?v=1782523565 | Y5: 105 | Z5: 257.75862 | AA5: =IF(AND(A5="", B5="", E5=""), "", IF(AB5="", "Válido", IF((LEN(AB5)-LEN(SUBSTITUTE(AB5,"; ","")))/2+1>(LEN(AB5)-LEN(SUBSTITUTE(AB5,"[Aviso]","")))/7, "Con Incidencias", "Válido"))) | AB5: =IF(AND(A5="", B5="", E5=""), "", TEXTJOIN("; ", TRUE, IF(OR(TRIM(A5&"")="", ISNUMBER(SEARCH("FALTA", A5))), "UPC faltante/inválido", ""), IF(AND(A5<>"", IFERROR(_xlfn.XMATCH(A5,$A$2:$A$12,0,1)<>_xlfn.XMATCH(A5,$A$2:$A$12,0,-1),FALSE)), "Código de barras duplicado", ""), IF(AND(E5<>"", COUNTIF($E$2:$E$12, E5)>1), "SKU duplicado", ""), IF(OR(J5="", J5=""), "[Aviso] División no capturada ()", IF(ISNA(MATCH(J5, Criterios!$A$123:$A$126, 0)), "División no válida", "")), IF(OR(K5="", K5=""), "[Aviso] Categoría no capturada ()", IF(ISNA(MATCH(K5, Criterios!$A$81:$A$120, 0)), "Categoría no válida", IF(AND(J5<>"", J5<>"", J5<>VLOOKUP(K5, Criterios!$A$81:$B$120, 2, FALSE)), "División no coincide con Categoría", ""))), IF(OR(L5="", L5=""), "[Aviso] Género no capturado ()", IF(ISNA(MATCH(L5, Criterios!$B$123:$B$127, 0)), "Género no válido", "")), IF(OR(N5="", N5=""), "[Aviso] Temporada no capturada ()", IF(ISNA(MATCH(N5, Criterios!$C$123:$C$128, 0)), "Temporada no válida", "")), IF(OR(O5="", O5=""), "[Aviso] Ciclo de vida no capturado ()", IF(ISNA(MATCH(O5, Criterios!$D$123:$D$124, 0)), "Ciclo de vida no válido", "")))) | AD5: 18 | AE5: WB OUTLET LERMA: 18 | AF5: 18 | AG5: Nuevo – NetSuite con existencia | AH5: Color por validar | Revisión 29/09/2026: Campos sin respaldo: P, X; Auditoría NetSuite 30/09/2026: llenado desde NetSuite [V,Y,T] | 01/10/2026: complementado desde Shopify Western Brothers (match por código de barras): WB Fit, WB Silueta, Enlace de imagen | 01/10/2026: Shopify Western Brothers trae Género «Mujer» — se conservó el valor de Productos | Homologación G1522 06/10/2026: WB País de origen: «USA» → «Estados Unidos» (Corrección aplicada) · Validación G1522: Dígito de control del código de barras inválido | AI5: No | AK5: ProductosCatalogoEstandar907.xlsx: fila 6176 [N,O,S,U,Y]; G1522_Extraccion_Articulos_NetSuite_2026-09-30.xlsx: fila 59397 [V,Y,T] | Shopify WB: producto 8577839169721 / variante 47786243817657 | AL5: 105 | AM5: 299 | AN5: Shopify Western Brothers | AP5: 18 | AR5: Shopify Western Brothers › Western Brothers Outlet Lerma: 18
A6: 182900115005 | B6: 111790 | C6: Multimarca | D6: WL0005 | E6: WL0005-UNI | F6: Talla única | G6: One Size | H6: Generico | I6: Llavero repujado con grabado | J6: Accesorios | K6: Llaveros | L6: Unisex | M6: Generico | N6: SS26 | O6: Seasonal | S6: 100% Piel | T6: Llavero repujado con grabado | U6: Estados Unidos | V6: PZS | W6: 46171515 | X6: https://cdn.shopify.com/s/files/1/0774/1849/6185/files/WhatsAppImage2026-06-25at4.38.37PM_1_1a0d602e-94d7-49a3-867d-70ce2c5119ff.jpg?v=1782523518 | Y6: 87.5 | Z6: 249 | AA6: =IF(AND(A6="", B6="", E6=""), "", IF(AB6="", "Válido", IF((LEN(AB6)-LEN(SUBSTITUTE(AB6,"; ","")))/2+1>(LEN(AB6)-LEN(SUBSTITUTE(AB6,"[Aviso]","")))/7, "Con Incidencias", "Válido"))) | AB6: =IF(AND(A6="", B6="", E6=""), "", TEXTJOIN("; ", TRUE, IF(OR(TRIM(A6&"")="", ISNUMBER(SEARCH("FALTA", A6))), "UPC faltante/inválido", ""), IF(AND(A6<>"", IFERROR(_xlfn.XMATCH(A6,$A$2:$A$12,0,1)<>_xlfn.XMATCH(A6,$A$2:$A$12,0,-1),FALSE)), "Código de barras duplicado", ""), IF(AND(E6<>"", COUNTIF($E$2:$E$12, E6)>1), "SKU duplicado", ""), IF(OR(J6="", J6=""), "[Aviso] División no capturada ()", IF(ISNA(MATCH(J6, Criterios!$A$123:$A$126, 0)), "División no válida", "")), IF(OR(K6="", K6=""), "[Aviso] Categoría no capturada ()", IF(ISNA(MATCH(K6, Criterios!$A$81:$A$120, 0)), "Categoría no válida", IF(AND(J6<>"", J6<>"", J6<>VLOOKUP(K6, Criterios!$A$81:$B$120, 2, FALSE)), "División no coincide con Categoría", ""))), IF(OR(L6="", L6=""), "[Aviso] Género no capturado ()", IF(ISNA(MATCH(L6, Criterios!$B$123:$B$127, 0)), "Género no válido", "")), IF(OR(N6="", N6=""), "[Aviso] Temporada no capturada ()", IF(ISNA(MATCH(N6, Criterios!$C$123:$C$128, 0)), "Temporada no válida", "")), IF(OR(O6="", O6=""), "[Aviso] Ciclo de vida no capturado ()", IF(ISNA(MATCH(O6, Criterios!$D$123:$D$124, 0)), "Ciclo de vida no válido", "")))) | AD6: 0 | AF6: 0 | AG6: Nuevo – NetSuite sin existencia | AH6: Color por validar; Clave SAT por validar | Revisión 29/09/2026: Campos sin respaldo: P, X; Auditoría NetSuite 30/09/2026: llenado desde NetSuite [V,Z,T] | 01/10/2026: complementado desde Shopify Western Brothers (match por código de barras): WB Fit, WB Silueta, Enlace de imagen | Homologación G1522 06/10/2026: WB País de origen: «USA» → «Estados Unidos» (Corrección aplicada) · Validador Shopify: WB: precio con IVA no termina en 9 | AI6: No | AK6: ProductosCatalogoEstandar907.xlsx: fila 6177 [N,O,S,U,W,Y]; G1522_Extraccion_Articulos_NetSuite_2026-09-30.xlsx: fila 59392 [V,Z,T] | Shopify WB: producto 8577839399097 / variante 47786244178105 | AL6: 87.5 | AM6: 249 | AN6: Shopify Western Brothers | AP6: 0
A7: 182900115006 | B7: 111791 | C7: Multimarca | D7: WL0006 | E7: WL0006-UNI | F7: Talla única | G7: One Size | H7: Generico | I7: Llavero repujado con ilustración | J7: Accesorios | K7: Llaveros | L7: Unisex | M7: Generico | N7: SS26 | O7: Seasonal | S7: 100% Piel | T7: Llavero repujado con ilustración | U7: Estados Unidos | V7: PZS | W7: 46171515 | X7: https://cdn.shopify.com/s/files/1/0774/1849/6185/files/WhatsAppImage2026-06-25at4.38.35PM.jpg?v=1782523473 | Y7: 87.5 | Z7: 249 | AA7: =IF(AND(A7="", B7="", E7=""), "", IF(AB7="", "Válido", IF((LEN(AB7)-LEN(SUBSTITUTE(AB7,"; ","")))/2+1>(LEN(AB7)-LEN(SUBSTITUTE(AB7,"[Aviso]","")))/7, "Con Incidencias", "Válido"))) | AB7: =IF(AND(A7="", B7="", E7=""), "", TEXTJOIN("; ", TRUE, IF(OR(TRIM(A7&"")="", ISNUMBER(SEARCH("FALTA", A7))), "UPC faltante/inválido", ""), IF(AND(A7<>"", IFERROR(_xlfn.XMATCH(A7,$A$2:$A$12,0,1)<>_xlfn.XMATCH(A7,$A$2:$A$12,0,-1),FALSE)), "Código de barras duplicado", ""), IF(AND(E7<>"", COUNTIF($E$2:$E$12, E7)>1), "SKU duplicado", ""), IF(OR(J7="", J7=""), "[Aviso] División no capturada ()", IF(ISNA(MATCH(J7, Criterios!$A$123:$A$126, 0)), "División no válida", "")), IF(OR(K7="", K7=""), "[Aviso] Categoría no capturada ()", IF(ISNA(MATCH(K7, Criterios!$A$81:$A$120, 0)), "Categoría no válida", IF(AND(J7<>"", J7<>"", J7<>VLOOKUP(K7, Criterios!$A$81:$B$120, 2, FALSE)), "División no coincide con Categoría", ""))), IF(OR(L7="", L7=""), "[Aviso] Género no capturado ()", IF(ISNA(MATCH(L7, Criterios!$B$123:$B$127, 0)), "Género no válido", "")), IF(OR(N7="", N7=""), "[Aviso] Temporada no capturada ()", IF(ISNA(MATCH(N7, Criterios!$C$123:$C$128, 0)), "Temporada no válida", "")), IF(OR(O7="", O7=""), "[Aviso] Ciclo de vida no capturado ()", IF(ISNA(MATCH(O7, Criterios!$D$123:$D$124, 0)), "Ciclo de vida no válido", "")))) | AD7: 9 | AE7: WB OUTLET LERMA: 9 | AF7: 9 | AG7: Nuevo – NetSuite con existencia | AH7: Color por validar; Clave SAT por validar | Revisión 29/09/2026: Campos sin respaldo: P, X; Auditoría NetSuite 30/09/2026: llenado desde NetSuite [V,Z,T] | 01/10/2026: complementado desde Shopify Western Brothers (match por código de barras): WB Fit, WB Silueta, Enlace de imagen | Homologación G1522 06/10/2026: WB País de origen: «USA» → «Estados Unidos» (Corrección aplicada) · Validación G1522: Dígito de control del código de barras inválido · Validador Shopify: WB: precio con IVA no termina en 9 | AI7: No | AK7: ProductosCatalogoEstandar907.xlsx: fila 6178 [N,O,S,U,W,Y]; G1522_Extraccion_Articulos_NetSuite_2026-09-30.xlsx: fila 59393 [V,Z,T] | Shopify WB: producto 8577839759545 / variante 47786244735161 | AL7: 87.5 | AM7: 249 | AN7: Shopify Western Brothers | AP7: 9 | AR7: Shopify Western Brothers › Western Brothers Outlet Lerma: 9
A8: 182900115007 | B8: 111792 | C8: Multimarca | D8: WL0007 | E8: WL0007-UNI | F8: Talla única | G8: One Size | H8: Generico | I8: Llavero contorno animal pelaje | J8: Accesorios | K8: Llaveros | L8: Unisex | M8: Generico | N8: SS26 | O8: Seasonal | S8: 100% Piel | T8: Llavero contorno animal pelaje | U8: Estados Unidos | V8: PZS | W8: 46171515 | X8: https://cdn.shopify.com/s/files/1/0774/1849/6185/files/WhatsAppImage2026-06-25at4.38.37PM.jpg?v=1782523454 | Y8: 43.75 | Z8: 149 | AA8: =IF(AND(A8="", B8="", E8=""), "", IF(AB8="", "Válido", IF((LEN(AB8)-LEN(SUBSTITUTE(AB8,"; ","")))/2+1>(LEN(AB8)-LEN(SUBSTITUTE(AB8,"[Aviso]","")))/7, "Con Incidencias", "Válido"))) | AB8: =IF(AND(A8="", B8="", E8=""), "", TEXTJOIN("; ", TRUE, IF(OR(TRIM(A8&"")="", ISNUMBER(SEARCH("FALTA", A8))), "UPC faltante/inválido", ""), IF(AND(A8<>"", IFERROR(_xlfn.XMATCH(A8,$A$2:$A$12,0,1)<>_xlfn.XMATCH(A8,$A$2:$A$12,0,-1),FALSE)), "Código de barras duplicado", ""), IF(AND(E8<>"", COUNTIF($E$2:$E$12, E8)>1), "SKU duplicado", ""), IF(OR(J8="", J8=""), "[Aviso] División no capturada ()", IF(ISNA(MATCH(J8, Criterios!$A$123:$A$126, 0)), "División no válida", "")), IF(OR(K8="", K8=""), "[Aviso] Categoría no capturada ()", IF(ISNA(MATCH(K8, Criterios!$A$81:$A$120, 0)), "Categoría no válida", IF(AND(J8<>"", J8<>"", J8<>VLOOKUP(K8, Criterios!$A$81:$B$120, 2, FALSE)), "División no coincide con Categoría", ""))), IF(OR(L8="", L8=""), "[Aviso] Género no capturado ()", IF(ISNA(MATCH(L8, Criterios!$B$123:$B$127, 0)), "Género no válido", "")), IF(OR(N8="", N8=""), "[Aviso] Temporada no capturada ()", IF(ISNA(MATCH(N8, Criterios!$C$123:$C$128, 0)), "Temporada no válida", "")), IF(OR(O8="", O8=""), "[Aviso] Ciclo de vida no capturado ()", IF(ISNA(MATCH(O8, Criterios!$D$123:$D$124, 0)), "Ciclo de vida no válido", "")))) | AD8: 0 | AF8: 0 | AG8: Nuevo – NetSuite con existencia | AH8: Color por validar; Clave SAT por validar | Revisión 29/09/2026: Campos sin respaldo: P, X; Auditoría NetSuite 30/09/2026: llenado desde NetSuite [V,Z,T] | 01/10/2026: complementado desde Shopify Western Brothers (match por código de barras): WB Fit, WB Silueta, Enlace de imagen | Homologación G1522 06/10/2026: WB País de origen: «USA» → «Estados Unidos» (Corrección aplicada) · Validación G1522: Dígito de control del código de barras inválido · Validador Shopify: WB: precio con IVA no termina en 9 | AI8: No | AK8: ProductosCatalogoEstandar907.xlsx: fila 6179 [N,O,S,U,W,Y]; G1522_Extraccion_Articulos_NetSuite_2026-09-30.xlsx: fila 59394 [V,Z,T] | Shopify WB: producto 8577840021689 / variante 47786244997305 | AL8: 43.75 | AM8: 149 | AN8: Shopify Western Brothers | AP8: 2 | AR8: Shopify Western Brothers › Western Brothers Outlet Lerma: 2
A9: 182900115008 | B9: 111793 | C9: Multimarca | D9: WL0008 | E9: WL0008-UNI | F9: Talla única | G9: One Size | H9: Generico | I9: Llavero destapador de asta | J9: Accesorios | K9: Llaveros | L9: Unisex | M9: Generico | N9: SS26 | O9: Seasonal | S9: Asta / Metal | T9: Llavero destapador de asta | U9: Estados Unidos | V9: PZS | W9: 46171515 | X9: https://cdn.shopify.com/s/files/1/0774/1849/6185/files/WhatsAppImage2026-06-25at4.38.36PM.jpg?v=1782523439 | Y9: 350 | Z9: 999 | AA9: =IF(AND(A9="", B9="", E9=""), "", IF(AB9="", "Válido", IF((LEN(AB9)-LEN(SUBSTITUTE(AB9,"; ","")))/2+1>(LEN(AB9)-LEN(SUBSTITUTE(AB9,"[Aviso]","")))/7, "Con Incidencias", "Válido"))) | AB9: =IF(AND(A9="", B9="", E9=""), "", TEXTJOIN("; ", TRUE, IF(OR(TRIM(A9&"")="", ISNUMBER(SEARCH("FALTA", A9))), "UPC faltante/inválido", ""), IF(AND(A9<>"", IFERROR(_xlfn.XMATCH(A9,$A$2:$A$12,0,1)<>_xlfn.XMATCH(A9,$A$2:$A$12,0,-1),FALSE)), "Código de barras duplicado", ""), IF(AND(E9<>"", COUNTIF($E$2:$E$12, E9)>1), "SKU duplicado", ""), IF(OR(J9="", J9=""), "[Aviso] División no capturada ()", IF(ISNA(MATCH(J9, Criterios!$A$123:$A$126, 0)), "División no válida", "")), IF(OR(K9="", K9=""), "[Aviso] Categoría no capturada ()", IF(ISNA(MATCH(K9, Criterios!$A$81:$A$120, 0)), "Categoría no válida", IF(AND(J9<>"", J9<>"", J9<>VLOOKUP(K9, Criterios!$A$81:$B$120, 2, FALSE)), "División no coincide con Categoría", ""))), IF(OR(L9="", L9=""), "[Aviso] Género no capturado ()", IF(ISNA(MATCH(L9, Criterios!$B$123:$B$127, 0)), "Género no válido", "")), IF(OR(N9="", N9=""), "[Aviso] Temporada no capturada ()", IF(ISNA(MATCH(N9, Criterios!$C$123:$C$128, 0)), "Temporada no válida", "")), IF(OR(O9="", O9=""), "[Aviso] Ciclo de vida no capturado ()", IF(ISNA(MATCH(O9, Criterios!$D$123:$D$124, 0)), "Ciclo de vida no válido", "")))) | AD9: 6 | AE9: WB OUTLET LERMA: 6 | AF9: 6 | AG9: Nuevo – NetSuite con existencia | AH9: Color por validar; Clave SAT por validar | Revisión 29/09/2026: Campos sin respaldo: P, X; Auditoría NetSuite 30/09/2026: llenado desde NetSuite [V,Z,T] | 01/10/2026: complementado desde Shopify Western Brothers (match por código de barras): WB Fit, WB Silueta, Enlace de imagen | Homologación G1522 06/10/2026: WB País de origen: «USA» → «Estados Unidos» (Corrección aplicada) · Validación G1522: Dígito de control del código de barras inválido · Validador Shopify: WB: precio con IVA no termina en 9 | AI9: No | AK9: ProductosCatalogoEstandar907.xlsx: fila 6180 [N,O,S,U,W,Y]; G1522_Extraccion_Articulos_NetSuite_2026-09-30.xlsx: fila 59395 [V,Z,T] | Shopify WB: producto 8577840152761 / variante 47786245128377 | AL9: 350 | AM9: 999 | AN9: Shopify Western Brothers | AP9: 6 | AR9: Shopify Western Brothers › Western Brothers Outlet Lerma: 6
A10: 182900115009 | B10: 111794 | C10: Multimarca | D10: WL0009 | E10: WL0009-UNI | F10: Talla única | G10: One Size | H10: Generico | I10: Llavero de crotal | J10: Accesorios | K10: Llaveros | L10: Unisex | M10: Generico | N10: SS26 | O10: Seasonal | S10: Plastico | T10: Llavero de crotal | U10: Estados Unidos | V10: PZS | W10: 46171515 | X10: https://cdn.shopify.com/s/files/1/0774/1849/6185/files/WhatsAppImage2026-06-25at4.38.36PM_1.jpg?v=1782523386 | Y10: 87.5 | Z10: 249 | AA10: =IF(AND(A10="", B10="", E10=""), "", IF(AB10="", "Válido", IF((LEN(AB10)-LEN(SUBSTITUTE(AB10,"; ","")))/2+1>(LEN(AB10)-LEN(SUBSTITUTE(AB10,"[Aviso]","")))/7, "Con Incidencias", "Válido"))) | AB10: =IF(AND(A10="", B10="", E10=""), "", TEXTJOIN("; ", TRUE, IF(OR(TRIM(A10&"")="", ISNUMBER(SEARCH("FALTA", A10))), "UPC faltante/inválido", ""), IF(AND(A10<>"", IFERROR(_xlfn.XMATCH(A10,$A$2:$A$12,0,1)<>_xlfn.XMATCH(A10,$A$2:$A$12,0,-1),FALSE)), "Código de barras duplicado", ""), IF(AND(E10<>"", COUNTIF($E$2:$E$12, E10)>1), "SKU duplicado", ""), IF(OR(J10="", J10=""), "[Aviso] División no capturada ()", IF(ISNA(MATCH(J10, Criterios!$A$123:$A$126, 0)), "División no válida", "")), IF(OR(K10="", K10=""), "[Aviso] Categoría no capturada ()", IF(ISNA(MATCH(K10, Criterios!$A$81:$A$120, 0)), "Categoría no válida", IF(AND(J10<>"", J10<>"", J10<>VLOOKUP(K10, Criterios!$A$81:$B$120, 2, FALSE)), "División no coincide con Categoría", ""))), IF(OR(L10="", L10=""), "[Aviso] Género no capturado ()", IF(ISNA(MATCH(L10, Criterios!$B$123:$B$127, 0)), "Género no válido", "")), IF(OR(N10="", N10=""), "[Aviso] Temporada no capturada ()", IF(ISNA(MATCH(N10, Criterios!$C$123:$C$128, 0)), "Temporada no válida", "")), IF(OR(O10="", O10=""), "[Aviso] Ciclo de vida no capturado ()", IF(ISNA(MATCH(O10, Criterios!$D$123:$D$124, 0)), "Ciclo de vida no válido", "")))) | AD10: 1 | AE10: WB OUTLET LERMA: 1 | AF10: 1 | AG10: Nuevo – NetSuite con existencia | AH10: Color por validar; Clave SAT por validar | Revisión 29/09/2026: Campos sin respaldo: P, X; Auditoría NetSuite 30/09/2026: llenado desde NetSuite [V,Z,T] | 01/10/2026: complementado desde Shopify Western Brothers (match por código de barras): WB Fit, WB Silueta, Enlace de imagen | Homologación G1522 06/10/2026: WB País de origen: «USA» → «Estados Unidos» (Corrección aplicada) · Validación G1522: Dígito de control del código de barras inválido · Validador Shopify: WB: precio con IVA no termina en 9 | AI10: No | AK10: ProductosCatalogoEstandar907.xlsx: fila 6181 [N,O,S,U,W,Y]; G1522_Extraccion_Articulos_NetSuite_2026-09-30.xlsx: fila 59396 [V,Z,T] | Shopify WB: producto 8577840283833 / variante 47786245259449 | AL10: 87.5 | AM10: 249 | AN10: Shopify Western Brothers | AP10: 1 | AR10: Shopify Western Brothers › Western Brothers Outlet Lerma: 1
A11: 182900115010 | B11: 111979 | C11: Multimarca | D11: WL0010 | E11: WL0010-UNI | F11: Talla única | G11: One Size | H11: Generico | I11: Pluma para Sombrero Chica | J11: Accesorios | K11: Plumas para sombrero | L11: Unisex | M11: Generico | N11: SS26 | O11: Seasonal | S11: Pluma | T11: Pluma para Sombrero Chica | U11: México | V11: PZS | W11: 11131501 | X11: https://cdn.shopify.com/s/files/1/0888/3250/8267/files/511-F1CRpuL._AC_SY350.jpg?v=1782767679 | Y11: 39 | Z11: 149 | AA11: =IF(AND(A11="", B11="", E11=""), "", IF(AB11="", "Válido", IF((LEN(AB11)-LEN(SUBSTITUTE(AB11,"; ","")))/2+1>(LEN(AB11)-LEN(SUBSTITUTE(AB11,"[Aviso]","")))/7, "Con Incidencias", "Válido"))) | AB11: =IF(AND(A11="", B11="", E11=""), "", TEXTJOIN("; ", TRUE, IF(OR(TRIM(A11&"")="", ISNUMBER(SEARCH("FALTA", A11))), "UPC faltante/inválido", ""), IF(AND(A11<>"", IFERROR(_xlfn.XMATCH(A11,$A$2:$A$12,0,1)<>_xlfn.XMATCH(A11,$A$2:$A$12,0,-1),FALSE)), "Código de barras duplicado", ""), IF(AND(E11<>"", COUNTIF($E$2:$E$12, E11)>1), "SKU duplicado", ""), IF(OR(J11="", J11=""), "[Aviso] División no capturada ()", IF(ISNA(MATCH(J11, Criterios!$A$123:$A$126, 0)), "División no válida", "")), IF(OR(K11="", K11=""), "[Aviso] Categoría no capturada ()", IF(ISNA(MATCH(K11, Criterios!$A$81:$A$120, 0)), "Categoría no válida", IF(AND(J11<>"", J11<>"", J11<>VLOOKUP(K11, Criterios!$A$81:$B$120, 2, FALSE)), "División no coincide con Categoría", ""))), IF(OR(L11="", L11=""), "[Aviso] Género no capturado ()", IF(ISNA(MATCH(L11, Criterios!$B$123:$B$127, 0)), "Género no válido", "")), IF(OR(N11="", N11=""), "[Aviso] Temporada no capturada ()", IF(ISNA(MATCH(N11, Criterios!$C$123:$C$128, 0)), "Temporada no válida", "")), IF(OR(O11="", O11=""), "[Aviso] Ciclo de vida no capturado ()", IF(ISNA(MATCH(O11, Criterios!$D$123:$D$124, 0)), "Ciclo de vida no válido", "")))) | AD11: 188 | AE11: STETSON AMERICAS: 157 | WB OUTLET LERMA: 35 | AF11: 192 | AG11: Nuevo – NetSuite con existencia | AH11: Color por validar; Clave SAT por validar; Stock negativo en sistema: revisar en conteo | Revisión 29/09/2026: Campos sin respaldo: P, X; Auditoría NetSuite 30/09/2026: llenado desde NetSuite [V,Z,T] | 01/10/2026: complementado desde Shopify Stetson México (match por código de barras): WB Fit, Enlace de imagen | 01/10/2026: Shopify Stetson México trae SKU WL0010, Categoría «Sombreros» — se conservó el valor de Productos | 01/10/2026: Shopify Western Brothers trae Categoría «Sombreros» — se conservó el valor de Productos | Homologación G1522 06/10/2026: WB País de origen: «MEX» → «México» (Corrección aplicada) · Validación G1522: Dígito de control del código de barras inválido · Validador Shopify: WB: precio con IVA no termina en 9 | AI11: Sí | AJ11: PUNTO DE VENTA: -4 | AK11: ProductosCatalogoEstandar907.xlsx: fila 6182 [N,O,S,U,W,Y]; G1522_Extraccion_Articulos_NetSuite_2026-09-30.xlsx: fila 59401 [V,Z,T] | Shopify Stetson: producto 15077633065323 / variante 53437448880491 | Shopify WB: producto 15405165150393 / variante 67616077840569 | AL11: 39 | AM11: 149 | AN11: Shopify Stetson México | Shopify Western Brothers | AO11: -3 | AP11: 0
A12: 182900115011 | B12: 111980 | C12: Multimarca | D12: WL0011 | E12: WL0011-UNI | F12: Talla única | G12: One Size | H12: Generico | I12: Pluma para Sombrero Grande | J12: Accesorios | K12: Plumas para sombrero | L12: Unisex | M12: Generico | N12: SS26 | O12: Seasonal | S12: Pluma | T12: Pluma para Sombrero Grande | U12: México | V12: PZS | W12: 11131501 | X12: https://cdn.shopify.com/s/files/1/0888/3250/8267/files/95641814-bfe1-428c-bc2c-44bda4da4671.551a4d940cf55518cd33c4132e59552b.jpg?v=1782767504 | Y12: 79 | Z12: 299 | AA12: =IF(AND(A12="", B12="", E12=""), "", IF(AB12="", "Válido", IF((LEN(AB12)-LEN(SUBSTITUTE(AB12,"; ","")))/2+1>(LEN(AB12)-LEN(SUBSTITUTE(AB12,"[Aviso]","")))/7, "Con Incidencias", "Válido"))) | AB12: =IF(AND(A12="", B12="", E12=""), "", TEXTJOIN("; ", TRUE, IF(OR(TRIM(A12&"")="", ISNUMBER(SEARCH("FALTA", A12))), "UPC faltante/inválido", ""), IF(AND(A12<>"", IFERROR(_xlfn.XMATCH(A12,$A$2:$A$12,0,1)<>_xlfn.XMATCH(A12,$A$2:$A$12,0,-1),FALSE)), "Código de barras duplicado", ""), IF(AND(E12<>"", COUNTIF($E$2:$E$12, E12)>1), "SKU duplicado", ""), IF(OR(J12="", J12=""), "[Aviso] División no capturada ()", IF(ISNA(MATCH(J12, Criterios!$A$123:$A$126, 0)), "División no válida", "")), IF(OR(K12="", K12=""), "[Aviso] Categoría no capturada ()", IF(ISNA(MATCH(K12, Criterios!$A$81:$A$120, 0)), "Categoría no válida", IF(AND(J12<>"", J12<>"", J12<>VLOOKUP(K12, Criterios!$A$81:$B$120, 2, FALSE)), "División no coincide con Categoría", ""))), IF(OR(L12="", L12=""), "[Aviso] Género no capturado ()", IF(ISNA(MATCH(L12, Criterios!$B$123:$B$127, 0)), "Género no válido", "")), IF(OR(N12="", N12=""), "[Aviso] Temporada no capturada ()", IF(ISNA(MATCH(N12, Criterios!$C$123:$C$128, 0)), "Temporada no válida", "")), IF(OR(O12="", O12=""), "[Aviso] Ciclo de vida no capturado ()", IF(ISNA(MATCH(O12, Criterios!$D$123:$D$124, 0)), "Ciclo de vida no válido", "")))) | AD12: 20 | AE12: STETSON AMERICAS: 10 | WB OUTLET LERMA: 10 | AF12: 20 | AG12: Nuevo – NetSuite con existencia | AH12: Color por validar; Clave SAT por validar | Revisión 29/09/2026: Campos sin respaldo: P, X; Auditoría NetSuite 30/09/2026: llenado desde NetSuite [V,Z,T] | 01/10/2026: complementado desde Shopify Stetson México (match por código de barras): WB Fit, Enlace de imagen | 01/10/2026: Shopify Stetson México trae SKU WL0011, Categoría «Sombreros» — se conservó el valor de Productos | 01/10/2026: Shopify Western Brothers trae Categoría «Sombreros» — se conservó el valor de Productos | Homologación G1522 06/10/2026: WB País de origen: «MEX» → «México» (Corrección aplicada) · Validación G1522: Dígito de control del código de barras inválido · Validador Shopify: WB: precio con IVA no termina en 9 | AI12: No | AK12: ProductosCatalogoEstandar907.xlsx: fila 6183 [N,O,S,U,W,Y]; G1522_Extraccion_Articulos_NetSuite_2026-09-30.xlsx: fila 59402 [V,Z,T] | Shopify Stetson: producto 15077632901483 / variante 53437448192363 | Shopify WB: producto 15405165412537 / variante 67616085606585 | AL12: 120 | AM12: 299 | AN12: Shopify Stetson México | Shopify Western Brothers | AO12: 15 | AP12: 0 | AR12: Shopify Stetson México › Stetson Americas: 15

Sheet Productos_Resumen
A1: UPC | B1: SKU | C1: Id_Interno | D1: Descripcion | E1: Talla_MX | F1: Talla_USA | G1: Precio_Compra | H1: Precio_Venta | I1: Stock_NetSuite | J1: Disponible_NetSuite | K1: Ubicaciones_NetSuite | L1: Stock_Shopify_Stetson | M1: Stock_Shopify_WB | N1: Stock_Odoo | O1: Stock_Plataformas_Total | P1: Ubicaciones_Plataformas | Q1: Piezas_Escaneadas | R1: Ubicacion_Escaneo
A2: =IFERROR(__xludf.DUMMYFUNCTION("ARRAY_CONSTRAIN(ARRAYFORMULA(LET(_xlpm.d,Productos!$A$2:$AR12,_xlpm.f,((INDEX(_xlpm.d,0,1)<>"""")+(INDEX(_xlpm.d,0,2)<>"""")+(INDEX(_xlpm.d,0,5)<>"""")+(INDEX(_xlpm.d,0,9)<>""""))>0,_xlpm.z,LAMBDA(_xlpm.c,IF(INDEX(_xlpm.d,0,_xlpm.c)="""",0,INDEX(_xlpm."&"d,0,_xlpm.c))),_xlpm.num,LAMBDA(_xlpm.v,IF(_xlpm.v="""","""",IF(ISTEXT(_xlpm.v),IFERROR(NUMBERVALUE(SUBSTITUTE(_xlpm.v,"","","".""),""."","",""),_xlpm.v),_xlpm.v))),_xlpm.pr,LAMBDA(_xlpm.a,_xlpm.b,_xlpm.num(IF(INDEX(_xlpm.d,0,_xlpm.a)<>"""",INDEX(_xlpm.d,"&"0,_xlpm.a),IF(INDEX(_xlpm.d,0,_xlpm.b)<>"""",INDEX(_xlpm.d,0,_xlpm.b),"""")))),_xlpm.pc,_xlpm.pr(38,25),_xlpm.pv,_xlpm.pr(39,26),_xlpm.tot,_xlpm.z(41)+_xlpm.z(42)+_xlpm.z(43),_xlpm.x,FILTER(HSTACK(CHOOSECOLS(_xlpm.d,1,5,2,9,6,7),_xlpm.pc,_xlpm.pv,CHOOSECO"&"LS(_xlpm.d,30,32,31,41,42,43),_xlpm.tot,INDEX(_xlpm.d,0,44)),_xlpm.f),IF(_xlpm.x="""","""",_xlpm.x))), 11, 16)"),"052356088867") | Q2: =IFERROR(__xludf.DUMMYFUNCTION("MAP(FILTER(A2:A12, (B2:B12<>"""")+(D2:D12<>"""")), FILTER(B2:B12, (B2:B12<>"""")+(D2:D12<>"""")), LAMBDA(upc, sku, LET(s_alt, IF(ISNUMBER(SEARCH(""-XXL"", sku)), SUBSTITUTE(sku, ""-XXL"", ""-2XL""), IF(ISNUMBER(SEARCH(""-2XL"", sku)), SU"&"BSTITUTE(sku, ""-2XL"", ""-XXL""), IF(ISNUMBER(SEARCH(""-XXXL"", sku)), SUBSTITUTE(sku, ""-XXXL"", ""-3XL""), IF(ISNUMBER(SEARCH(""-3XL"", sku)), SUBSTITUTE(sku, ""-3XL"", ""-XXXL""), sku)))), pz_exact, IF(sku<>"""", SUMIFS(Table_2[Piezas Contadas], Table"&"_2[SKU], sku), 0), pz_alt, IF(s_alt<>sku, SUMIFS(Table_2[Piezas Contadas], Table_2[SKU], s_alt), 0), pz_upc_blank, IF(upc<>"""", SUMIFS(Table_2[Piezas Contadas], Table_2[UPC CODE], upc, Table_2[SKU], """"), 0), pz_exact + pz_alt + pz_upc_blank)))"),0.0) | R2: =IFERROR(__xludf.DUMMYFUNCTION("MAP(FILTER(A2:A12, (B2:B12<>"""")+(D2:D12<>"""")), FILTER(B2:B12, (B2:B12<>"""")+(D2:D12<>"""")), FILTER(Q2:Q12, (B2:B12<>"""")+(D2:D12<>"""")), LAMBDA(upc, sku, pz, IF(OR(pz=0, pz=""""), """", LET(s_alt, IF(ISNUMBER(SEARCH(""-X"&"XL"", sku)), SUBSTITUTE(sku, ""-XXL"", ""-2XL""), IF(ISNUMBER(SEARCH(""-2XL"", sku)), SUBSTITUTE(sku, ""-2XL"", ""-XXL""), IF(ISNUMBER(SEARCH(""-XXXL"", sku)), SUBSTITUTE(sku, ""-XXXL"", ""-3XL""), IF(ISNUMBER(SEARCH(""-3XL"", sku)), SUBSTITUTE(sku, ""-3X"&"L"", ""-XXXL""), sku)))), rk_sku, IFERROR(FILTER(Table_2[Ubicación / Rack], Table_2[SKU]=sku, Table_2[Ubicación / Rack]<>""""), """"), rk_alt, IF(s_alt<>sku, IFERROR(FILTER(Table_2[Ubicación / Rack], Table_2[SKU]=s_alt, Table_2[Ubicación / Rack]<>""""), "&"""""), """"), rk_upc, IF(upc<>"""", IFERROR(FILTER(Table_2[Ubicación / Rack], Table_2[UPC CODE]=upc, Table_2[SKU]="""", Table_2[Ubicación / Rack]<>""""), """"), """"), all_r, VSTACK(rk_sku, rk_alt, rk_upc), r_uniq, UNIQUE(IFERROR(FILTER(all_r, all_r<>"""""&"), """")), IF(INDEX(r_uniq, 1, 1)="""", """", TEXTJOIN("", "", TRUE, MAP(r_uniq, LAMBDA(rk, LET(cnt_sku, IF(sku<>"""", SUMIFS(Table_2[Piezas Contadas], Table_2[SKU], sku, Table_2[Ubicación / Rack], rk), 0), cnt_alt, IF(s_alt<>sku, SUMIFS(Table_2[Piezas Co"&"ntadas], Table_2[SKU], s_alt, Table_2[Ubicación / Rack], rk), 0), cnt_upc, IF(upc<>"""", SUMIFS(Table_2[Piezas Contadas], Table_2[UPC CODE], upc, Table_2[SKU], """", Table_2[Ubicación / Rack], rk), 0), rk & "" ("" & (cnt_sku + cnt_alt + cnt_upc) & "")""))"&")))))))"),"")

Sheet Criterios
A1: Criterios del Catálogo Estándar
A2: Guía de llenado y listas de valores válidos. Usa el índice para saltar a cada sección; sigue la Ruta de llenado en orden.
